{
	"document_title": "Security update for python-dnspython",
	"document_type": "SUSE Patch",
	"document_publisher": {
		"type": "Vendor",
		"contact_details": "security@suse.de",
		"issuing_authority": "SUSE Security Team"
	},
	"document_tracking": {
		"identification": {
			"id": "SUSE-SU-2024:3297-1"
		},
		"status": "Final",
		"version": "1",
		"revision_history": {
			"revision": {
				"number": "1",
				"date": "2024-09-18T10:56:55Z",
				"description": "current"
			}
		},
		"initial_release_date": "2024-09-18T10:56:55Z",
		"current_release_date": "2024-09-18T10:56:55Z",
		"generator": {
			"engine": "cve-database/bin/generate-cvrf.pl",
			"date": "2017-02-24T01:00:00Z"
		}
	},
	"document_notes": [
		{
			"text": "Security update for python-dnspython",
			"title": "Topic",
			"type": "Summary"
		},
		{
			"text": "This update for python-dnspython fixes the following issue:\n\n- Fix CVE-2023-29483 (bsc#1230353).\n",
			"title": "Details",
			"type": "General"
		},
		{
			"text": "The CVRF data is provided by SUSE under the Creative Commons License 4.0 with Attribution (CC-BY-4.0).",
			"title": "Terms of Use",
			"type": "Legal Disclaimer"
		},
		{
			"text": "SUSE-2024-3297,SUSE-SLE-Module-Public-Cloud-12-2024-3297",
			"title": "Patchnames",
			"type": "Details"
		}
	],
	"documentdistribution": "Copyright SUSE LLC under the Creative Commons License 4.0 with Attribution (CC-BY-4.0)",
	"document_references": [
		{
			"type": "Self",
			"url": "https://www.suse.com/support/update/announcement/2024/suse-su-20243297-1/",
			"description": "Link for SUSE-SU-2024:3297-1"
		},
		{
			"type": "Self",
			"url": "https://lists.suse.com/pipermail/sle-security-updates/2024-September/019448.html",
			"description": "E-Mail link for SUSE-SU-2024:3297-1"
		},
		{
			"type": "Self",
			"url": "https://www.suse.com/support/security/rating/",
			"description": "SUSE Security Ratings"
		},
		{
			"type": "Self",
			"url": "https://bugzilla.suse.com/1230353",
			"description": "SUSE Bug 1230353"
		},
		{
			"type": "Self",
			"url": "https://www.suse.com/security/cve/CVE-2023-29483/",
			"description": "SUSE CVE CVE-2023-29483 page"
		}
	],
	"product_tree": {
		"branch": [
			{
				"type": "Product Family",
				"name": "SUSE Linux Enterprise Module for Public Cloud 12",
				"branch": [
					{
						"type": "Product Name",
						"name": "SUSE Linux Enterprise Module for Public Cloud 12",
						"full_product_name": {
							"text": "SUSE Linux Enterprise Module for Public Cloud 12",
							"product_id": "SUSE Linux Enterprise Module for Public Cloud 12",
							"cpe": "cpe:/o:suse:sle-module-public-cloud:12"
						}
					}
				],
				"full_product_name": {}
			},
			{
				"type": "Product Version",
				"name": "python-dnspython-1.12.0-9.16.2",
				"full_product_name": {
					"text": "python-dnspython-1.12.0-9.16.2",
					"product_id": "python-dnspython-1.12.0-9.16.2"
				}
			},
			{
				"type": "Product Version",
				"name": "python3-dnspython-1.12.0-9.16.2",
				"full_product_name": {
					"text": "python3-dnspython-1.12.0-9.16.2",
					"product_id": "python3-dnspython-1.12.0-9.16.2"
				}
			}
		],
		"relationship": [
			{
				"product_reference": "python-dnspython-1.12.0-9.16.2",
				"relation_type": "Default Component Of",
				"relates_to_product_reference": "SUSE Linux Enterprise Module for Public Cloud 12"
			},
			{
				"product_reference": "python3-dnspython-1.12.0-9.16.2",
				"relation_type": "Default Component Of",
				"relates_to_product_reference": "SUSE Linux Enterprise Module for Public Cloud 12"
			}
		]
	},
	"vulnerability": [
		{
			"notes": [
				{
					"text": "eventlet before 0.35.2, as used in dnspython before 2.6.0, allows remote attackers to interfere with DNS name resolution by quickly sending an invalid packet from the expected IP address and source port, aka a \"TuDoor\" attack. In other words, dnspython does not have the preferred behavior in which the DNS name resolution algorithm would proceed, within the full time window, in order to wait for a valid packet. NOTE: dnspython 2.6.0 is unusable for a different reason that was addressed in 2.6.1.",
					"title": "Vulnerability Description",
					"type": "General"
				}
			],
			"cve": "CVE-2023-29483",
			"product_statuses": [
				{
					"type": "Fixed",
					"product_id": [
						"SUSE Linux Enterprise Module for Public Cloud 12:python-dnspython-1.12.0-9.16.2",
						"SUSE Linux Enterprise Module for Public Cloud 12:python3-dnspython-1.12.0-9.16.2"
					]
				}
			],
			"threats": [
				{
					"type": "Impact",
					"description": "moderate"
				}
			],
			"cvss_score_sets": {
				"score_set_v_2": {},
				"score_set_v_3": {
					"base_score_v_3": "5.9",
					"vector_v_3": "CVSS:3.1/AV:N/AC:H/PR:N/UI:N/S:U/C:N/I:N/A:H"
				},
				"scoreset": {}
			},
			"remediations": [
				{
					"type": "Vendor Fix",
					"description": {
						"text": "To install this SUSE Security Update use the SUSE recommended installation methods like YaST online_update or \"zypper patch\".\n",
						"lang": "en"
					},
					"url": "https://www.suse.com/support/update/announcement/2024/suse-su-20243297-1/"
				}
			],
			"references": [
				{
					"url": "https://www.suse.com/security/cve/CVE-2023-29483.html",
					"description": "CVE-2023-29483"
				},
				{
					"url": "https://bugzilla.suse.com/1222693",
					"description": "SUSE Bug 1222693"
				}
			]
		}
	]
}
