{
	"document_title": "Security update for python-PyKMIP",
	"document_type": "SUSE Patch",
	"document_publisher": {
		"type": "Vendor",
		"contact_details": "security@suse.de",
		"issuing_authority": "SUSE Security Team"
	},
	"document_tracking": {
		"identification": {
			"id": "SUSE-SU-2019:0391-1"
		},
		"status": "Final",
		"version": "1",
		"revision_history": {
			"revision": {
				"number": "1",
				"date": "2019-02-14T13:44:35Z",
				"description": "current"
			}
		},
		"initial_release_date": "2019-02-14T13:44:35Z",
		"current_release_date": "2019-02-14T13:44:35Z",
		"generator": {
			"engine": "cve-database/bin/generate-cvrf.pl",
			"date": "2017-02-24T01:00:00Z"
		}
	},
	"document_notes": [
		{
			"text": "Security update for python-PyKMIP",
			"title": "Topic",
			"type": "Summary"
		},
		{
			"text": "This update for python-PyKMIP fixes the following issues:\n\nSecurity issue fixed:\n\n- CVE-2018-1000872: Fixed a denial-of-service vulnerability which was caused by exhausting \n  the available sockets. To mitigate the issue server socket timeout was decreased (bsc#1120767).\n",
			"title": "Details",
			"type": "General"
		},
		{
			"text": "The CVRF data is provided by SUSE under the Creative Commons License 4.0 with Attribution (CC-BY-4.0).",
			"title": "Terms of Use",
			"type": "Legal Disclaimer"
		},
		{
			"text": "HPE-Helion-OpenStack-8-2019-391,SUSE-2019-391,SUSE-OpenStack-Cloud-8-2019-391,SUSE-OpenStack-Cloud-Crowbar-8-2019-391",
			"title": "Patchnames",
			"type": "Details"
		}
	],
	"documentdistribution": "Copyright SUSE LLC under the Creative Commons License 4.0 with Attribution (CC-BY-4.0)",
	"document_references": [
		{
			"type": "Self",
			"url": "https://www.suse.com/support/update/announcement/2019/suse-su-20190391-1/",
			"description": "Link for SUSE-SU-2019:0391-1"
		},
		{
			"type": "Self",
			"url": "https://lists.suse.com/pipermail/sle-security-updates/2019-February/005119.html",
			"description": "E-Mail link for SUSE-SU-2019:0391-1"
		},
		{
			"type": "Self",
			"url": "https://www.suse.com/support/security/rating/",
			"description": "SUSE Security Ratings"
		},
		{
			"type": "Self",
			"url": "https://bugzilla.suse.com/1120767",
			"description": "SUSE Bug 1120767"
		},
		{
			"type": "Self",
			"url": "https://www.suse.com/security/cve/CVE-2018-1000872/",
			"description": "SUSE CVE CVE-2018-1000872 page"
		}
	],
	"product_tree": {
		"branch": [
			{
				"type": "Product Family",
				"name": "HPE Helion OpenStack 8",
				"branch": [
					{
						"type": "Product Name",
						"name": "HPE Helion OpenStack 8",
						"full_product_name": {
							"text": "HPE Helion OpenStack 8",
							"product_id": "HPE Helion OpenStack 8",
							"cpe": "cpe:/o:suse:hpe-helion-openstack:8"
						}
					}
				],
				"full_product_name": {}
			},
			{
				"type": "Product Family",
				"name": "SUSE OpenStack Cloud 8",
				"branch": [
					{
						"type": "Product Name",
						"name": "SUSE OpenStack Cloud 8",
						"full_product_name": {
							"text": "SUSE OpenStack Cloud 8",
							"product_id": "SUSE OpenStack Cloud 8",
							"cpe": "cpe:/o:suse:suse-openstack-cloud:8"
						}
					}
				],
				"full_product_name": {}
			},
			{
				"type": "Product Family",
				"name": "SUSE OpenStack Cloud Crowbar 8",
				"branch": [
					{
						"type": "Product Name",
						"name": "SUSE OpenStack Cloud Crowbar 8",
						"full_product_name": {
							"text": "SUSE OpenStack Cloud Crowbar 8",
							"product_id": "SUSE OpenStack Cloud Crowbar 8",
							"cpe": "cpe:/o:suse:suse-openstack-cloud-crowbar:8"
						}
					}
				],
				"full_product_name": {}
			},
			{
				"type": "Product Version",
				"name": "python-PyKMIP-0.6.0-3.3.1",
				"full_product_name": {
					"text": "python-PyKMIP-0.6.0-3.3.1",
					"product_id": "python-PyKMIP-0.6.0-3.3.1"
				}
			},
			{
				"type": "Product Version",
				"name": "python3-PyKMIP-0.6.0-3.3.1",
				"full_product_name": {
					"text": "python3-PyKMIP-0.6.0-3.3.1",
					"product_id": "python3-PyKMIP-0.6.0-3.3.1"
				}
			}
		],
		"relationship": [
			{
				"product_reference": "python-PyKMIP-0.6.0-3.3.1",
				"relation_type": "Default Component Of",
				"relates_to_product_reference": "HPE Helion OpenStack 8"
			},
			{
				"product_reference": "python-PyKMIP-0.6.0-3.3.1",
				"relation_type": "Default Component Of",
				"relates_to_product_reference": "SUSE OpenStack Cloud 8"
			},
			{
				"product_reference": "python-PyKMIP-0.6.0-3.3.1",
				"relation_type": "Default Component Of",
				"relates_to_product_reference": "SUSE OpenStack Cloud Crowbar 8"
			}
		]
	},
	"vulnerability": [
		{
			"notes": [
				{
					"text": "OpenKMIP PyKMIP version All versions before 0.8.0 contains a CWE 399: Resource Management Errors (similar issue to CVE-2015-5262) vulnerability in PyKMIP server that can result in DOS: the server can be made unavailable by one or more clients opening all of the available sockets. This attack appear to be exploitable via A client or clients open sockets with the server and then never close them. This vulnerability appears to have been fixed in 0.8.0.",
					"title": "Vulnerability Description",
					"type": "General"
				}
			],
			"cve": "CVE-2018-1000872",
			"product_statuses": [
				{
					"type": "Fixed",
					"product_id": [
						"HPE Helion OpenStack 8:python-PyKMIP-0.6.0-3.3.1",
						"SUSE OpenStack Cloud 8:python-PyKMIP-0.6.0-3.3.1",
						"SUSE OpenStack Cloud Crowbar 8:python-PyKMIP-0.6.0-3.3.1"
					]
				}
			],
			"threats": [
				{
					"type": "Impact",
					"description": "important"
				}
			],
			"cvss_score_sets": {
				"score_set_v_2": {
					"base_score_v_2": "4.3",
					"vector_v_2": "AV:N/AC:M/Au:N/C:N/I:N/A:P"
				},
				"score_set_v_3": {
					"base_score_v_3": "7.5",
					"vector_v_3": "CVSS:3.0/AV:N/AC:L/PR:N/UI:N/S:U/C:N/I:N/A:H"
				},
				"scoreset": {}
			},
			"remediations": [
				{
					"type": "Vendor Fix",
					"description": {
						"text": "To install this SUSE Security Update use the SUSE recommended installation methods like YaST online_update or \"zypper patch\".\n",
						"lang": "en"
					},
					"url": "https://www.suse.com/support/update/announcement/2019/suse-su-20190391-1/"
				}
			],
			"references": [
				{
					"url": "https://www.suse.com/security/cve/CVE-2018-1000872.html",
					"description": "CVE-2018-1000872"
				},
				{
					"url": "https://bugzilla.suse.com/1120767",
					"description": "SUSE Bug 1120767"
				}
			]
		}
	]
}
