{
	"document_title": "Security update for python-Django",
	"document_type": "SUSE Patch",
	"document_publisher": {
		"type": "Vendor",
		"contact_details": "security@suse.de",
		"issuing_authority": "SUSE Security Team"
	},
	"document_tracking": {
		"identification": {
			"id": "SUSE-SU-2019:3127-1"
		},
		"status": "Final",
		"version": "1",
		"revision_history": {
			"revision": {
				"number": "1",
				"date": "2019-11-29T16:21:37Z",
				"description": "current"
			}
		},
		"initial_release_date": "2019-11-29T16:21:37Z",
		"current_release_date": "2019-11-29T16:21:37Z",
		"generator": {
			"engine": "cve-database/bin/generate-cvrf.pl",
			"date": "2017-02-24T01:00:00Z"
		}
	},
	"document_notes": [
		{
			"text": "Security update for python-Django",
			"title": "Topic",
			"type": "Summary"
		},
		{
			"text": "This update for python-Django fixes the following issues:\n\n- CVE-2019-12781: Added incorrect HTTP detection with reverse-proxy \n  connecting via HTTPS (bsc#1139945).\n- CVE-2019-3498: Fixed a content spoofing via crafted URL in the default \n  404 page (bsc#1120932).\n",
			"title": "Details",
			"type": "General"
		},
		{
			"text": "The CVRF data is provided by SUSE under the Creative Commons License 4.0 with Attribution (CC-BY-4.0).",
			"title": "Terms of Use",
			"type": "Legal Disclaimer"
		},
		{
			"text": "SUSE-2019-3127,SUSE-Storage-5-2019-3127",
			"title": "Patchnames",
			"type": "Details"
		}
	],
	"documentdistribution": "Copyright SUSE LLC under the Creative Commons License 4.0 with Attribution (CC-BY-4.0)",
	"document_references": [
		{
			"type": "Self",
			"url": "https://www.suse.com/support/update/announcement/2019/suse-su-20193127-1/",
			"description": "Link for SUSE-SU-2019:3127-1"
		},
		{
			"type": "Self",
			"url": "https://lists.suse.com/pipermail/sle-security-updates/2019-November/006204.html",
			"description": "E-Mail link for SUSE-SU-2019:3127-1"
		},
		{
			"type": "Self",
			"url": "https://www.suse.com/support/security/rating/",
			"description": "SUSE Security Ratings"
		},
		{
			"type": "Self",
			"url": "https://bugzilla.suse.com/1120932",
			"description": "SUSE Bug 1120932"
		},
		{
			"type": "Self",
			"url": "https://bugzilla.suse.com/1139945",
			"description": "SUSE Bug 1139945"
		},
		{
			"type": "Self",
			"url": "https://www.suse.com/security/cve/CVE-2019-12781/",
			"description": "SUSE CVE CVE-2019-12781 page"
		},
		{
			"type": "Self",
			"url": "https://www.suse.com/security/cve/CVE-2019-3498/",
			"description": "SUSE CVE CVE-2019-3498 page"
		}
	],
	"product_tree": {
		"branch": [
			{
				"type": "Product Family",
				"name": "SUSE Enterprise Storage 5",
				"branch": [
					{
						"type": "Product Name",
						"name": "SUSE Enterprise Storage 5",
						"full_product_name": {
							"text": "SUSE Enterprise Storage 5",
							"product_id": "SUSE Enterprise Storage 5",
							"cpe": "cpe:/o:suse:ses:5"
						}
					}
				],
				"full_product_name": {}
			},
			{
				"type": "Product Version",
				"name": "python-Django-1.6.11-6.10.1",
				"full_product_name": {
					"text": "python-Django-1.6.11-6.10.1",
					"product_id": "python-Django-1.6.11-6.10.1"
				}
			}
		],
		"relationship": [
			{
				"product_reference": "python-Django-1.6.11-6.10.1",
				"relation_type": "Default Component Of",
				"relates_to_product_reference": "SUSE Enterprise Storage 5"
			}
		]
	},
	"vulnerability": [
		{
			"notes": [
				{
					"text": "An issue was discovered in Django 1.11 before 1.11.22, 2.1 before 2.1.10, and 2.2 before 2.2.3. An HTTP request is not redirected to HTTPS when the SECURE_PROXY_SSL_HEADER and SECURE_SSL_REDIRECT settings are used, and the proxy connects to Django via HTTPS. In other words, django.http.HttpRequest.scheme has incorrect behavior when a client uses HTTP.",
					"title": "Vulnerability Description",
					"type": "General"
				}
			],
			"cve": "CVE-2019-12781",
			"product_statuses": [
				{
					"type": "Fixed",
					"product_id": [
						"SUSE Enterprise Storage 5:python-Django-1.6.11-6.10.1"
					]
				}
			],
			"threats": [
				{
					"type": "Impact",
					"description": "moderate"
				}
			],
			"cvss_score_sets": {
				"score_set_v_2": {
					"base_score_v_2": "5",
					"vector_v_2": "AV:N/AC:L/Au:N/C:P/I:N/A:N"
				},
				"score_set_v_3": {
					"base_score_v_3": "6.5",
					"vector_v_3": "CVSS:3.0/AV:N/AC:L/PR:N/UI:N/S:U/C:L/I:L/A:N"
				},
				"scoreset": {}
			},
			"remediations": [
				{
					"type": "Vendor Fix",
					"description": {
						"text": "To install this SUSE Security Update use the SUSE recommended installation methods like YaST online_update or \"zypper patch\".\n",
						"lang": "en"
					},
					"url": "https://www.suse.com/support/update/announcement/2019/suse-su-20193127-1/"
				}
			],
			"references": [
				{
					"url": "https://www.suse.com/security/cve/CVE-2019-12781.html",
					"description": "CVE-2019-12781"
				},
				{
					"url": "https://bugzilla.suse.com/1124991",
					"description": "SUSE Bug 1124991"
				},
				{
					"url": "https://bugzilla.suse.com/1139945",
					"description": "SUSE Bug 1139945"
				}
			]
		},
		{
			"notes": [
				{
					"text": "In Django 1.11.x before 1.11.18, 2.0.x before 2.0.10, and 2.1.x before 2.1.5, an Improper Neutralization of Special Elements in Output Used by a Downstream Component issue exists in django.views.defaults.page_not_found(), leading to content spoofing (in a 404 error page) if a user fails to recognize that a crafted URL has malicious content.",
					"title": "Vulnerability Description",
					"type": "General"
				}
			],
			"cve": "CVE-2019-3498",
			"product_statuses": [
				{
					"type": "Fixed",
					"product_id": [
						"SUSE Enterprise Storage 5:python-Django-1.6.11-6.10.1"
					]
				}
			],
			"threats": [
				{
					"type": "Impact",
					"description": "low"
				}
			],
			"cvss_score_sets": {
				"score_set_v_2": {
					"base_score_v_2": "4.3",
					"vector_v_2": "AV:N/AC:M/Au:N/C:N/I:P/A:N"
				},
				"score_set_v_3": {
					"base_score_v_3": "4.3",
					"vector_v_3": "CVSS:3.0/AV:N/AC:L/PR:N/UI:R/S:U/C:N/I:L/A:N"
				},
				"scoreset": {}
			},
			"remediations": [
				{
					"type": "Vendor Fix",
					"description": {
						"text": "To install this SUSE Security Update use the SUSE recommended installation methods like YaST online_update or \"zypper patch\".\n",
						"lang": "en"
					},
					"url": "https://www.suse.com/support/update/announcement/2019/suse-su-20193127-1/"
				}
			],
			"references": [
				{
					"url": "https://www.suse.com/security/cve/CVE-2019-3498.html",
					"description": "CVE-2019-3498"
				},
				{
					"url": "https://bugzilla.suse.com/1120932",
					"description": "SUSE Bug 1120932"
				},
				{
					"url": "https://bugzilla.suse.com/1139945",
					"description": "SUSE Bug 1139945"
				}
			]
		}
	]
}
