{
	"document_title": "Security update for python-Django1",
	"document_type": "SUSE Patch",
	"document_publisher": {
		"type": "Vendor",
		"contact_details": "security@suse.de",
		"issuing_authority": "SUSE Security Team"
	},
	"document_tracking": {
		"identification": {
			"id": "SUSE-SU-2023:3533-1"
		},
		"status": "Final",
		"version": "1",
		"revision_history": {
			"revision": {
				"number": "1",
				"date": "2023-09-05T12:39:26Z",
				"description": "current"
			}
		},
		"initial_release_date": "2023-09-05T12:39:26Z",
		"current_release_date": "2023-09-05T12:39:26Z",
		"generator": {
			"engine": "cve-database/bin/generate-cvrf.pl",
			"date": "2017-02-24T01:00:00Z"
		}
	},
	"document_notes": [
		{
			"text": "Security update for python-Django1",
			"title": "Topic",
			"type": "Summary"
		},
		{
			"text": "This update for python-Django1 fixes the following issues:\n\n- CVE-2023-41164: Fixed a potential denial of service vulnerability in django.utils.encoding.uri_to_iri() (bsc#1214667).\n",
			"title": "Details",
			"type": "General"
		},
		{
			"text": "The CVRF data is provided by SUSE under the Creative Commons License 4.0 with Attribution (CC-BY-4.0).",
			"title": "Terms of Use",
			"type": "Legal Disclaimer"
		},
		{
			"text": "SUSE-2023-3533,SUSE-OpenStack-Cloud-9-2023-3533,SUSE-OpenStack-Cloud-Crowbar-9-2023-3533",
			"title": "Patchnames",
			"type": "Details"
		}
	],
	"documentdistribution": "Copyright SUSE LLC under the Creative Commons License 4.0 with Attribution (CC-BY-4.0)",
	"document_references": [
		{
			"type": "Self",
			"url": "https://www.suse.com/support/update/announcement/2023/suse-su-20233533-1/",
			"description": "Link for SUSE-SU-2023:3533-1"
		},
		{
			"type": "Self",
			"url": "https://lists.suse.com/pipermail/sle-updates/2023-September/031348.html",
			"description": "E-Mail link for SUSE-SU-2023:3533-1"
		},
		{
			"type": "Self",
			"url": "https://www.suse.com/support/security/rating/",
			"description": "SUSE Security Ratings"
		},
		{
			"type": "Self",
			"url": "https://bugzilla.suse.com/1214667",
			"description": "SUSE Bug 1214667"
		},
		{
			"type": "Self",
			"url": "https://www.suse.com/security/cve/CVE-2023-41164/",
			"description": "SUSE CVE CVE-2023-41164 page"
		}
	],
	"product_tree": {
		"branch": [
			{
				"type": "Product Family",
				"name": "SUSE OpenStack Cloud 9",
				"branch": [
					{
						"type": "Product Name",
						"name": "SUSE OpenStack Cloud 9",
						"full_product_name": {
							"text": "SUSE OpenStack Cloud 9",
							"product_id": "SUSE OpenStack Cloud 9",
							"cpe": "cpe:/o:suse:suse-openstack-cloud:9"
						}
					}
				],
				"full_product_name": {}
			},
			{
				"type": "Product Family",
				"name": "SUSE OpenStack Cloud Crowbar 9",
				"branch": [
					{
						"type": "Product Name",
						"name": "SUSE OpenStack Cloud Crowbar 9",
						"full_product_name": {
							"text": "SUSE OpenStack Cloud Crowbar 9",
							"product_id": "SUSE OpenStack Cloud Crowbar 9",
							"cpe": "cpe:/o:suse:suse-openstack-cloud-crowbar:9"
						}
					}
				],
				"full_product_name": {}
			},
			{
				"type": "Product Version",
				"name": "python-Django1-1.11.29-3.50.1",
				"full_product_name": {
					"text": "python-Django1-1.11.29-3.50.1",
					"product_id": "python-Django1-1.11.29-3.50.1"
				}
			},
			{
				"type": "Product Version",
				"name": "python3-Django1-1.11.29-3.50.1",
				"full_product_name": {
					"text": "python3-Django1-1.11.29-3.50.1",
					"product_id": "python3-Django1-1.11.29-3.50.1"
				}
			}
		],
		"relationship": [
			{
				"product_reference": "python-Django1-1.11.29-3.50.1",
				"relation_type": "Default Component Of",
				"relates_to_product_reference": "SUSE OpenStack Cloud 9"
			},
			{
				"product_reference": "python-Django1-1.11.29-3.50.1",
				"relation_type": "Default Component Of",
				"relates_to_product_reference": "SUSE OpenStack Cloud Crowbar 9"
			}
		]
	},
	"vulnerability": [
		{
			"notes": [
				{
					"text": "In Django 3.2 before 3.2.21, 4.1 before 4.1.11, and 4.2 before 4.2.5, django.utils.encoding.uri_to_iri() is subject to a potential DoS (denial of service) attack via certain inputs with a very large number of Unicode characters.",
					"title": "Vulnerability Description",
					"type": "General"
				}
			],
			"cve": "CVE-2023-41164",
			"product_statuses": [
				{
					"type": "Fixed",
					"product_id": [
						"SUSE OpenStack Cloud 9:python-Django1-1.11.29-3.50.1",
						"SUSE OpenStack Cloud Crowbar 9:python-Django1-1.11.29-3.50.1"
					]
				}
			],
			"threats": [
				{
					"type": "Impact",
					"description": "moderate"
				}
			],
			"cvss_score_sets": {
				"score_set_v_2": {},
				"score_set_v_3": {
					"base_score_v_3": "6.5",
					"vector_v_3": "CVSS:3.1/AV:N/AC:L/PR:N/UI:N/S:U/C:N/I:L/A:L"
				},
				"scoreset": {}
			},
			"remediations": [
				{
					"type": "Vendor Fix",
					"description": {
						"text": "To install this SUSE Security Update use the SUSE recommended installation methods like YaST online_update or \"zypper patch\".\n",
						"lang": "en"
					},
					"url": "https://www.suse.com/support/update/announcement/2023/suse-su-20233533-1/"
				}
			],
			"references": [
				{
					"url": "https://www.suse.com/security/cve/CVE-2023-41164.html",
					"description": "CVE-2023-41164"
				},
				{
					"url": "https://bugzilla.suse.com/1214667",
					"description": "SUSE Bug 1214667"
				}
			]
		}
	]
}
