{
	"document_title": "python313-3.13.0~b3-1.1 on GA media",
	"document_type": "SUSE Patch",
	"document_publisher": {
		"type": "Vendor",
		"contact_details": "security@suse.de",
		"issuing_authority": "SUSE Security Team"
	},
	"document_tracking": {
		"identification": {
			"id": "openSUSE-SU-2024:14109-1"
		},
		"status": "Final",
		"version": "1",
		"revision_history": {
			"revision": {
				"number": "1",
				"date": "2024-08-10T21:46:02Z",
				"description": "current"
			}
		},
		"initial_release_date": "2024-08-10T21:46:02Z",
		"current_release_date": "2024-08-10T21:46:02Z",
		"generator": {
			"engine": "cve-database/bin/generate-cvrf.pl",
			"date": "2017-02-24T01:00:00Z"
		}
	},
	"document_notes": [
		{
			"text": "python313-3.13.0~b3-1.1 on GA media",
			"title": "Topic",
			"type": "Summary"
		},
		{
			"text": "These are all security issues fixed in the python313-3.13.0~b3-1.1 package on the GA media of openSUSE Tumbleweed.",
			"title": "Details",
			"type": "General"
		},
		{
			"text": "The CVRF data is provided by SUSE under the Creative Commons License 4.0 with Attribution (CC-BY-4.0).",
			"title": "Terms of Use",
			"type": "Legal Disclaimer"
		},
		{
			"text": "openSUSE-Tumbleweed-2024-14109",
			"title": "Patchnames",
			"type": "Details"
		}
	],
	"documentdistribution": "Copyright SUSE LLC under the Creative Commons License 4.0 with Attribution (CC-BY-4.0)",
	"document_references": [
		{
			"type": "Self",
			"url": "https://www.suse.com/support/security/rating/",
			"description": "SUSE Security Ratings"
		},
		{
			"type": "Self",
			"url": "https://www.suse.com/security/cve/CVE-2011-3389/",
			"description": "SUSE CVE CVE-2011-3389 page"
		},
		{
			"type": "Self",
			"url": "https://www.suse.com/security/cve/CVE-2011-4944/",
			"description": "SUSE CVE CVE-2011-4944 page"
		},
		{
			"type": "Self",
			"url": "https://www.suse.com/security/cve/CVE-2012-0845/",
			"description": "SUSE CVE CVE-2012-0845 page"
		},
		{
			"type": "Self",
			"url": "https://www.suse.com/security/cve/CVE-2012-1150/",
			"description": "SUSE CVE CVE-2012-1150 page"
		},
		{
			"type": "Self",
			"url": "https://www.suse.com/security/cve/CVE-2013-1752/",
			"description": "SUSE CVE CVE-2013-1752 page"
		},
		{
			"type": "Self",
			"url": "https://www.suse.com/security/cve/CVE-2013-4238/",
			"description": "SUSE CVE CVE-2013-4238 page"
		},
		{
			"type": "Self",
			"url": "https://www.suse.com/security/cve/CVE-2014-2667/",
			"description": "SUSE CVE CVE-2014-2667 page"
		},
		{
			"type": "Self",
			"url": "https://www.suse.com/security/cve/CVE-2014-4650/",
			"description": "SUSE CVE CVE-2014-4650 page"
		},
		{
			"type": "Self",
			"url": "https://www.suse.com/security/cve/CVE-2019-20907/",
			"description": "SUSE CVE CVE-2019-20907 page"
		},
		{
			"type": "Self",
			"url": "https://www.suse.com/security/cve/CVE-2019-5010/",
			"description": "SUSE CVE CVE-2019-5010 page"
		},
		{
			"type": "Self",
			"url": "https://www.suse.com/security/cve/CVE-2019-9947/",
			"description": "SUSE CVE CVE-2019-9947 page"
		},
		{
			"type": "Self",
			"url": "https://www.suse.com/security/cve/CVE-2020-10735/",
			"description": "SUSE CVE CVE-2020-10735 page"
		},
		{
			"type": "Self",
			"url": "https://www.suse.com/security/cve/CVE-2020-15523/",
			"description": "SUSE CVE CVE-2020-15523 page"
		},
		{
			"type": "Self",
			"url": "https://www.suse.com/security/cve/CVE-2020-15801/",
			"description": "SUSE CVE CVE-2020-15801 page"
		},
		{
			"type": "Self",
			"url": "https://www.suse.com/security/cve/CVE-2020-8492/",
			"description": "SUSE CVE CVE-2020-8492 page"
		},
		{
			"type": "Self",
			"url": "https://www.suse.com/security/cve/CVE-2021-23336/",
			"description": "SUSE CVE CVE-2021-23336 page"
		},
		{
			"type": "Self",
			"url": "https://www.suse.com/security/cve/CVE-2021-3177/",
			"description": "SUSE CVE CVE-2021-3177 page"
		},
		{
			"type": "Self",
			"url": "https://www.suse.com/security/cve/CVE-2021-3426/",
			"description": "SUSE CVE CVE-2021-3426 page"
		},
		{
			"type": "Self",
			"url": "https://www.suse.com/security/cve/CVE-2022-25236/",
			"description": "SUSE CVE CVE-2022-25236 page"
		},
		{
			"type": "Self",
			"url": "https://www.suse.com/security/cve/CVE-2022-42919/",
			"description": "SUSE CVE CVE-2022-42919 page"
		},
		{
			"type": "Self",
			"url": "https://www.suse.com/security/cve/CVE-2022-45061/",
			"description": "SUSE CVE CVE-2022-45061 page"
		},
		{
			"type": "Self",
			"url": "https://www.suse.com/security/cve/CVE-2023-0286/",
			"description": "SUSE CVE CVE-2023-0286 page"
		},
		{
			"type": "Self",
			"url": "https://www.suse.com/security/cve/CVE-2023-24329/",
			"description": "SUSE CVE CVE-2023-24329 page"
		},
		{
			"type": "Self",
			"url": "https://www.suse.com/security/cve/CVE-2023-2650/",
			"description": "SUSE CVE CVE-2023-2650 page"
		},
		{
			"type": "Self",
			"url": "https://www.suse.com/security/cve/CVE-2023-27043/",
			"description": "SUSE CVE CVE-2023-27043 page"
		},
		{
			"type": "Self",
			"url": "https://www.suse.com/security/cve/CVE-2023-40217/",
			"description": "SUSE CVE CVE-2023-40217 page"
		},
		{
			"type": "Self",
			"url": "https://www.suse.com/security/cve/CVE-2023-52425/",
			"description": "SUSE CVE CVE-2023-52425 page"
		},
		{
			"type": "Self",
			"url": "https://www.suse.com/security/cve/CVE-2024-4030/",
			"description": "SUSE CVE CVE-2024-4030 page"
		}
	],
	"product_tree": {
		"branch": [
			{
				"type": "Product Family",
				"name": "openSUSE Tumbleweed",
				"branch": [
					{
						"type": "Product Name",
						"name": "openSUSE Tumbleweed",
						"full_product_name": {
							"text": "openSUSE Tumbleweed",
							"product_id": "openSUSE Tumbleweed",
							"cpe": "cpe:/o:opensuse:tumbleweed"
						}
					}
				],
				"full_product_name": {}
			},
			{
				"type": "Product Version",
				"name": "python313-3.13.0~b3-1.1",
				"full_product_name": {
					"text": "python313-3.13.0~b3-1.1",
					"product_id": "python313-3.13.0~b3-1.1"
				}
			},
			{
				"type": "Product Version",
				"name": "python313-curses-3.13.0~b3-1.1",
				"full_product_name": {
					"text": "python313-curses-3.13.0~b3-1.1",
					"product_id": "python313-curses-3.13.0~b3-1.1"
				}
			},
			{
				"type": "Product Version",
				"name": "python313-dbm-3.13.0~b3-1.1",
				"full_product_name": {
					"text": "python313-dbm-3.13.0~b3-1.1",
					"product_id": "python313-dbm-3.13.0~b3-1.1"
				}
			},
			{
				"type": "Product Version",
				"name": "python313-idle-3.13.0~b3-1.1",
				"full_product_name": {
					"text": "python313-idle-3.13.0~b3-1.1",
					"product_id": "python313-idle-3.13.0~b3-1.1"
				}
			},
			{
				"type": "Product Version",
				"name": "python313-tk-3.13.0~b3-1.1",
				"full_product_name": {
					"text": "python313-tk-3.13.0~b3-1.1",
					"product_id": "python313-tk-3.13.0~b3-1.1"
				}
			},
			{
				"type": "Product Version",
				"name": "python313-x86-64-v3-3.13.0~b3-1.1",
				"full_product_name": {
					"text": "python313-x86-64-v3-3.13.0~b3-1.1",
					"product_id": "python313-x86-64-v3-3.13.0~b3-1.1"
				}
			}
		],
		"relationship": [
			{
				"product_reference": "python313-3.13.0~b3-1.1",
				"relation_type": "Default Component Of",
				"relates_to_product_reference": "openSUSE Tumbleweed"
			},
			{
				"product_reference": "python313-curses-3.13.0~b3-1.1",
				"relation_type": "Default Component Of",
				"relates_to_product_reference": "openSUSE Tumbleweed"
			},
			{
				"product_reference": "python313-dbm-3.13.0~b3-1.1",
				"relation_type": "Default Component Of",
				"relates_to_product_reference": "openSUSE Tumbleweed"
			},
			{
				"product_reference": "python313-idle-3.13.0~b3-1.1",
				"relation_type": "Default Component Of",
				"relates_to_product_reference": "openSUSE Tumbleweed"
			},
			{
				"product_reference": "python313-tk-3.13.0~b3-1.1",
				"relation_type": "Default Component Of",
				"relates_to_product_reference": "openSUSE Tumbleweed"
			},
			{
				"product_reference": "python313-x86-64-v3-3.13.0~b3-1.1",
				"relation_type": "Default Component Of",
				"relates_to_product_reference": "openSUSE Tumbleweed"
			}
		]
	},
	"vulnerability": [
		{
			"notes": [
				{
					"text": "The SSL protocol, as used in certain configurations in Microsoft Windows and Microsoft Internet Explorer, Mozilla Firefox, Google Chrome, Opera, and other products, encrypts data by using CBC mode with chained initialization vectors, which allows man-in-the-middle attackers to obtain plaintext HTTP headers via a blockwise chosen-boundary attack (BCBA) on an HTTPS session, in conjunction with JavaScript code that uses (1) the HTML5 WebSocket API, (2) the Java URLConnection API, or (3) the Silverlight WebClient API, aka a \"BEAST\" attack.",
					"title": "Vulnerability Description",
					"type": "General"
				}
			],
			"cve": "CVE-2011-3389",
			"product_statuses": [
				{
					"type": "Fixed",
					"product_id": [
						"openSUSE Tumbleweed:python313-3.13.0~b3-1.1",
						"openSUSE Tumbleweed:python313-curses-3.13.0~b3-1.1",
						"openSUSE Tumbleweed:python313-dbm-3.13.0~b3-1.1",
						"openSUSE Tumbleweed:python313-idle-3.13.0~b3-1.1",
						"openSUSE Tumbleweed:python313-tk-3.13.0~b3-1.1",
						"openSUSE Tumbleweed:python313-x86-64-v3-3.13.0~b3-1.1"
					]
				}
			],
			"threats": [
				{
					"type": "Impact",
					"description": "moderate"
				}
			],
			"cvss_score_sets": {
				"score_set_v_2": {
					"base_score_v_2": "4.3",
					"vector_v_2": "AV:N/AC:M/Au:N/C:P/I:N/A:N"
				},
				"score_set_v_3": {
					"base_score_v_3": "3.7",
					"vector_v_3": "CVSS:3.1/AV:N/AC:H/PR:N/UI:N/S:U/C:L/I:N/A:N"
				},
				"scoreset": {}
			},
			"remediations": [
				{
					"type": "Vendor Fix",
					"description": {
						"text": "To install this SUSE Security Update use the SUSE recommended installation methods like YaST online_update or \"zypper patch\".\n",
						"lang": "en"
					}
				}
			],
			"references": [
				{
					"url": "https://www.suse.com/security/cve/CVE-2011-3389.html",
					"description": "CVE-2011-3389"
				},
				{
					"url": "https://bugzilla.suse.com/716002",
					"description": "SUSE Bug 716002"
				},
				{
					"url": "https://bugzilla.suse.com/719047",
					"description": "SUSE Bug 719047"
				},
				{
					"url": "https://bugzilla.suse.com/725167",
					"description": "SUSE Bug 725167"
				},
				{
					"url": "https://bugzilla.suse.com/726096",
					"description": "SUSE Bug 726096"
				},
				{
					"url": "https://bugzilla.suse.com/739248",
					"description": "SUSE Bug 739248"
				},
				{
					"url": "https://bugzilla.suse.com/739256",
					"description": "SUSE Bug 739256"
				},
				{
					"url": "https://bugzilla.suse.com/742306",
					"description": "SUSE Bug 742306"
				},
				{
					"url": "https://bugzilla.suse.com/751718",
					"description": "SUSE Bug 751718"
				},
				{
					"url": "https://bugzilla.suse.com/759666",
					"description": "SUSE Bug 759666"
				},
				{
					"url": "https://bugzilla.suse.com/763598",
					"description": "SUSE Bug 763598"
				},
				{
					"url": "https://bugzilla.suse.com/814655",
					"description": "SUSE Bug 814655"
				}
			]
		},
		{
			"notes": [
				{
					"text": "Python 2.6 through 3.2 creates ~/.pypirc with world-readable permissions before changing them after data has been written, which introduces a race condition that allows local users to obtain a username and password by reading this file.",
					"title": "Vulnerability Description",
					"type": "General"
				}
			],
			"cve": "CVE-2011-4944",
			"product_statuses": [
				{
					"type": "Fixed",
					"product_id": [
						"openSUSE Tumbleweed:python313-3.13.0~b3-1.1",
						"openSUSE Tumbleweed:python313-curses-3.13.0~b3-1.1",
						"openSUSE Tumbleweed:python313-dbm-3.13.0~b3-1.1",
						"openSUSE Tumbleweed:python313-idle-3.13.0~b3-1.1",
						"openSUSE Tumbleweed:python313-tk-3.13.0~b3-1.1",
						"openSUSE Tumbleweed:python313-x86-64-v3-3.13.0~b3-1.1"
					]
				}
			],
			"threats": [
				{
					"type": "Impact",
					"description": "low"
				}
			],
			"cvss_score_sets": {
				"score_set_v_2": {
					"base_score_v_2": "1.9",
					"vector_v_2": "AV:L/AC:M/Au:N/C:P/I:N/A:N"
				},
				"score_set_v_3": {
					"base_score_v_3": "3.3",
					"vector_v_3": "CVSS:3.1/AV:L/AC:L/PR:L/UI:N/S:U/C:L/I:N/A:N"
				},
				"scoreset": {}
			},
			"remediations": [
				{
					"type": "Vendor Fix",
					"description": {
						"text": "To install this SUSE Security Update use the SUSE recommended installation methods like YaST online_update or \"zypper patch\".\n",
						"lang": "en"
					}
				}
			],
			"references": [
				{
					"url": "https://www.suse.com/security/cve/CVE-2011-4944.html",
					"description": "CVE-2011-4944"
				},
				{
					"url": "https://bugzilla.suse.com/754447",
					"description": "SUSE Bug 754447"
				}
			]
		},
		{
			"notes": [
				{
					"text": "SimpleXMLRPCServer.py in SimpleXMLRPCServer in Python before 2.6.8, 2.7.x before 2.7.3, 3.x before 3.1.5, and 3.2.x before 3.2.3 allows remote attackers to cause a denial of service (infinite loop and CPU consumption) via an XML-RPC POST request that contains a smaller amount of data than specified by the Content-Length header.",
					"title": "Vulnerability Description",
					"type": "General"
				}
			],
			"cve": "CVE-2012-0845",
			"product_statuses": [
				{
					"type": "Fixed",
					"product_id": [
						"openSUSE Tumbleweed:python313-3.13.0~b3-1.1",
						"openSUSE Tumbleweed:python313-curses-3.13.0~b3-1.1",
						"openSUSE Tumbleweed:python313-dbm-3.13.0~b3-1.1",
						"openSUSE Tumbleweed:python313-idle-3.13.0~b3-1.1",
						"openSUSE Tumbleweed:python313-tk-3.13.0~b3-1.1",
						"openSUSE Tumbleweed:python313-x86-64-v3-3.13.0~b3-1.1"
					]
				}
			],
			"threats": [
				{
					"type": "Impact",
					"description": "moderate"
				}
			],
			"cvss_score_sets": {
				"score_set_v_2": {
					"base_score_v_2": "5",
					"vector_v_2": "AV:N/AC:L/Au:N/C:N/I:N/A:P"
				},
				"score_set_v_3": {
					"base_score_v_3": "5.3",
					"vector_v_3": "CVSS:3.1/AV:N/AC:L/PR:N/UI:N/S:U/C:N/I:N/A:L"
				},
				"scoreset": {}
			},
			"remediations": [
				{
					"type": "Vendor Fix",
					"description": {
						"text": "To install this SUSE Security Update use the SUSE recommended installation methods like YaST online_update or \"zypper patch\".\n",
						"lang": "en"
					}
				}
			],
			"references": [
				{
					"url": "https://www.suse.com/security/cve/CVE-2012-0845.html",
					"description": "CVE-2012-0845"
				},
				{
					"url": "https://bugzilla.suse.com/747125",
					"description": "SUSE Bug 747125"
				}
			]
		},
		{
			"notes": [
				{
					"text": "Python before 2.6.8, 2.7.x before 2.7.3, 3.x before 3.1.5, and 3.2.x before 3.2.3 computes hash values without restricting the ability to trigger hash collisions predictably, which allows context-dependent attackers to cause a denial of service (CPU consumption) via crafted input to an application that maintains a hash table.",
					"title": "Vulnerability Description",
					"type": "General"
				}
			],
			"cve": "CVE-2012-1150",
			"product_statuses": [
				{
					"type": "Fixed",
					"product_id": [
						"openSUSE Tumbleweed:python313-3.13.0~b3-1.1",
						"openSUSE Tumbleweed:python313-curses-3.13.0~b3-1.1",
						"openSUSE Tumbleweed:python313-dbm-3.13.0~b3-1.1",
						"openSUSE Tumbleweed:python313-idle-3.13.0~b3-1.1",
						"openSUSE Tumbleweed:python313-tk-3.13.0~b3-1.1",
						"openSUSE Tumbleweed:python313-x86-64-v3-3.13.0~b3-1.1"
					]
				}
			],
			"threats": [
				{
					"type": "Impact",
					"description": "moderate"
				}
			],
			"cvss_score_sets": {
				"score_set_v_2": {
					"base_score_v_2": "5",
					"vector_v_2": "AV:N/AC:L/Au:N/C:N/I:N/A:P"
				},
				"score_set_v_3": {
					"base_score_v_3": "5.3",
					"vector_v_3": "CVSS:3.1/AV:N/AC:L/PR:N/UI:N/S:U/C:N/I:N/A:L"
				},
				"scoreset": {}
			},
			"remediations": [
				{
					"type": "Vendor Fix",
					"description": {
						"text": "To install this SUSE Security Update use the SUSE recommended installation methods like YaST online_update or \"zypper patch\".\n",
						"lang": "en"
					}
				}
			],
			"references": [
				{
					"url": "https://www.suse.com/security/cve/CVE-2012-1150.html",
					"description": "CVE-2012-1150"
				},
				{
					"url": "https://bugzilla.suse.com/751718",
					"description": "SUSE Bug 751718"
				},
				{
					"url": "https://bugzilla.suse.com/755383",
					"description": "SUSE Bug 755383"
				},
				{
					"url": "https://bugzilla.suse.com/826682",
					"description": "SUSE Bug 826682"
				}
			]
		},
		{
			"notes": [
				{
					"text": "** REJECT ** Various versions of Python do not properly restrict readline calls, which allows remote attackers to cause a denial of service (memory consumption) via a long string, related to (1) httplib - fixed in 2.7.4, 2.6.9, and 3.3.3; (2) ftplib - fixed in 2.7.6, 2.6.9, 3.3.3; (3) imaplib - not yet fixed in 2.7.x, fixed in 2.6.9, 3.3.3; (4) nntplib - fixed in 2.7.6, 2.6.9, 3.3.3; (5) poplib - not yet fixed in 2.7.x, fixed in 2.6.9, 3.3.3; and (6) smtplib - not yet fixed in 2.7.x, fixed in 2.6.9, not yet fixed in 3.3.x. NOTE: this was REJECTed because it is incompatible with CNT1 \"Independently Fixable\" in the CVE Counting Decisions.",
					"title": "Vulnerability Description",
					"type": "General"
				}
			],
			"cve": "CVE-2013-1752",
			"product_statuses": [
				{
					"type": "Fixed",
					"product_id": [
						"openSUSE Tumbleweed:python313-3.13.0~b3-1.1",
						"openSUSE Tumbleweed:python313-curses-3.13.0~b3-1.1",
						"openSUSE Tumbleweed:python313-dbm-3.13.0~b3-1.1",
						"openSUSE Tumbleweed:python313-idle-3.13.0~b3-1.1",
						"openSUSE Tumbleweed:python313-tk-3.13.0~b3-1.1",
						"openSUSE Tumbleweed:python313-x86-64-v3-3.13.0~b3-1.1"
					]
				}
			],
			"threats": [
				{
					"type": "Impact",
					"description": "moderate"
				}
			],
			"cvss_score_sets": {
				"score_set_v_2": {},
				"score_set_v_3": {
					"base_score_v_3": "5.3",
					"vector_v_3": "CVSS:3.1/AV:N/AC:L/PR:N/UI:N/S:U/C:N/I:N/A:L"
				},
				"scoreset": {}
			},
			"remediations": [
				{
					"type": "Vendor Fix",
					"description": {
						"text": "To install this SUSE Security Update use the SUSE recommended installation methods like YaST online_update or \"zypper patch\".\n",
						"lang": "en"
					}
				}
			],
			"references": [
				{
					"url": "https://www.suse.com/security/cve/CVE-2013-1752.html",
					"description": "CVE-2013-1752"
				},
				{
					"url": "https://bugzilla.suse.com/856835",
					"description": "SUSE Bug 856835"
				},
				{
					"url": "https://bugzilla.suse.com/856836",
					"description": "SUSE Bug 856836"
				},
				{
					"url": "https://bugzilla.suse.com/863741",
					"description": "SUSE Bug 863741"
				},
				{
					"url": "https://bugzilla.suse.com/885882",
					"description": "SUSE Bug 885882"
				},
				{
					"url": "https://bugzilla.suse.com/898572",
					"description": "SUSE Bug 898572"
				},
				{
					"url": "https://bugzilla.suse.com/912739",
					"description": "SUSE Bug 912739"
				}
			]
		},
		{
			"notes": [
				{
					"text": "The ssl.match_hostname function in the SSL module in Python 2.6 through 3.4 does not properly handle a '\\0' character in a domain name in the Subject Alternative Name field of an X.509 certificate, which allows man-in-the-middle attackers to spoof arbitrary SSL servers via a crafted certificate issued by a legitimate Certification Authority, a related issue to CVE-2009-2408.",
					"title": "Vulnerability Description",
					"type": "General"
				}
			],
			"cve": "CVE-2013-4238",
			"product_statuses": [
				{
					"type": "Fixed",
					"product_id": [
						"openSUSE Tumbleweed:python313-3.13.0~b3-1.1",
						"openSUSE Tumbleweed:python313-curses-3.13.0~b3-1.1",
						"openSUSE Tumbleweed:python313-dbm-3.13.0~b3-1.1",
						"openSUSE Tumbleweed:python313-idle-3.13.0~b3-1.1",
						"openSUSE Tumbleweed:python313-tk-3.13.0~b3-1.1",
						"openSUSE Tumbleweed:python313-x86-64-v3-3.13.0~b3-1.1"
					]
				}
			],
			"threats": [
				{
					"type": "Impact",
					"description": "moderate"
				}
			],
			"cvss_score_sets": {
				"score_set_v_2": {
					"base_score_v_2": "4.3",
					"vector_v_2": "AV:N/AC:M/Au:N/C:N/I:P/A:N"
				},
				"score_set_v_3": {
					"base_score_v_3": "5.3",
					"vector_v_3": "CVSS:3.1/AV:N/AC:L/PR:N/UI:N/S:U/C:N/I:L/A:N"
				},
				"scoreset": {}
			},
			"remediations": [
				{
					"type": "Vendor Fix",
					"description": {
						"text": "To install this SUSE Security Update use the SUSE recommended installation methods like YaST online_update or \"zypper patch\".\n",
						"lang": "en"
					}
				}
			],
			"references": [
				{
					"url": "https://www.suse.com/security/cve/CVE-2013-4238.html",
					"description": "CVE-2013-4238"
				},
				{
					"url": "https://bugzilla.suse.com/834601",
					"description": "SUSE Bug 834601"
				},
				{
					"url": "https://bugzilla.suse.com/839107",
					"description": "SUSE Bug 839107"
				},
				{
					"url": "https://bugzilla.suse.com/882915",
					"description": "SUSE Bug 882915"
				},
				{
					"url": "https://bugzilla.suse.com/912739",
					"description": "SUSE Bug 912739"
				}
			]
		},
		{
			"notes": [
				{
					"text": "Race condition in the _get_masked_mode function in Lib/os.py in Python 3.2 through 3.5, when exist_ok is set to true and multiple threads are used, might allow local users to bypass intended file permissions by leveraging a separate application vulnerability before the umask has been set to the expected value.",
					"title": "Vulnerability Description",
					"type": "General"
				}
			],
			"cve": "CVE-2014-2667",
			"product_statuses": [
				{
					"type": "Fixed",
					"product_id": [
						"openSUSE Tumbleweed:python313-3.13.0~b3-1.1",
						"openSUSE Tumbleweed:python313-curses-3.13.0~b3-1.1",
						"openSUSE Tumbleweed:python313-dbm-3.13.0~b3-1.1",
						"openSUSE Tumbleweed:python313-idle-3.13.0~b3-1.1",
						"openSUSE Tumbleweed:python313-tk-3.13.0~b3-1.1",
						"openSUSE Tumbleweed:python313-x86-64-v3-3.13.0~b3-1.1"
					]
				}
			],
			"threats": [
				{
					"type": "Impact",
					"description": "moderate"
				}
			],
			"cvss_score_sets": {
				"score_set_v_2": {
					"base_score_v_2": "3.3",
					"vector_v_2": "AV:L/AC:M/Au:N/C:P/I:P/A:N"
				},
				"score_set_v_3": {
					"base_score_v_3": "5.3",
					"vector_v_3": "CVSS:3.1/AV:L/AC:L/PR:L/UI:N/S:U/C:L/I:L/A:L"
				},
				"scoreset": {}
			},
			"remediations": [
				{
					"type": "Vendor Fix",
					"description": {
						"text": "To install this SUSE Security Update use the SUSE recommended installation methods like YaST online_update or \"zypper patch\".\n",
						"lang": "en"
					}
				}
			],
			"references": [
				{
					"url": "https://www.suse.com/security/cve/CVE-2014-2667.html",
					"description": "CVE-2014-2667"
				},
				{
					"url": "https://bugzilla.suse.com/871152",
					"description": "SUSE Bug 871152"
				}
			]
		},
		{
			"notes": [
				{
					"text": "The CGIHTTPServer module in Python 2.7.5 and 3.3.4 does not properly handle URLs in which URL encoding is used for path separators, which allows remote attackers to read script source code or conduct directory traversal attacks and execute unintended code via a crafted character sequence, as demonstrated by a %2f separator.",
					"title": "Vulnerability Description",
					"type": "General"
				}
			],
			"cve": "CVE-2014-4650",
			"product_statuses": [
				{
					"type": "Fixed",
					"product_id": [
						"openSUSE Tumbleweed:python313-3.13.0~b3-1.1",
						"openSUSE Tumbleweed:python313-curses-3.13.0~b3-1.1",
						"openSUSE Tumbleweed:python313-dbm-3.13.0~b3-1.1",
						"openSUSE Tumbleweed:python313-idle-3.13.0~b3-1.1",
						"openSUSE Tumbleweed:python313-tk-3.13.0~b3-1.1",
						"openSUSE Tumbleweed:python313-x86-64-v3-3.13.0~b3-1.1"
					]
				}
			],
			"threats": [
				{
					"type": "Impact",
					"description": "moderate"
				}
			],
			"cvss_score_sets": {
				"score_set_v_2": {
					"base_score_v_2": "7.5",
					"vector_v_2": "AV:N/AC:L/Au:N/C:P/I:P/A:P"
				},
				"score_set_v_3": {
					"base_score_v_3": "5.3",
					"vector_v_3": "CVSS:3.1/AV:N/AC:L/PR:N/UI:N/S:U/C:L/I:N/A:N"
				},
				"scoreset": {}
			},
			"remediations": [
				{
					"type": "Vendor Fix",
					"description": {
						"text": "To install this SUSE Security Update use the SUSE recommended installation methods like YaST online_update or \"zypper patch\".\n",
						"lang": "en"
					}
				}
			],
			"references": [
				{
					"url": "https://www.suse.com/security/cve/CVE-2014-4650.html",
					"description": "CVE-2014-4650"
				},
				{
					"url": "https://bugzilla.suse.com/856835",
					"description": "SUSE Bug 856835"
				},
				{
					"url": "https://bugzilla.suse.com/856836",
					"description": "SUSE Bug 856836"
				},
				{
					"url": "https://bugzilla.suse.com/863741",
					"description": "SUSE Bug 863741"
				},
				{
					"url": "https://bugzilla.suse.com/885882",
					"description": "SUSE Bug 885882"
				},
				{
					"url": "https://bugzilla.suse.com/898572",
					"description": "SUSE Bug 898572"
				},
				{
					"url": "https://bugzilla.suse.com/912739",
					"description": "SUSE Bug 912739"
				}
			]
		},
		{
			"notes": [
				{
					"text": "In Lib/tarfile.py in Python through 3.8.3, an attacker is able to craft a TAR archive leading to an infinite loop when opened by tarfile.open, because _proc_pax lacks header validation.",
					"title": "Vulnerability Description",
					"type": "General"
				}
			],
			"cve": "CVE-2019-20907",
			"product_statuses": [
				{
					"type": "Fixed",
					"product_id": [
						"openSUSE Tumbleweed:python313-3.13.0~b3-1.1",
						"openSUSE Tumbleweed:python313-curses-3.13.0~b3-1.1",
						"openSUSE Tumbleweed:python313-dbm-3.13.0~b3-1.1",
						"openSUSE Tumbleweed:python313-idle-3.13.0~b3-1.1",
						"openSUSE Tumbleweed:python313-tk-3.13.0~b3-1.1",
						"openSUSE Tumbleweed:python313-x86-64-v3-3.13.0~b3-1.1"
					]
				}
			],
			"threats": [
				{
					"type": "Impact",
					"description": "moderate"
				}
			],
			"cvss_score_sets": {
				"score_set_v_2": {
					"base_score_v_2": "5",
					"vector_v_2": "AV:N/AC:L/Au:N/C:N/I:N/A:P"
				},
				"score_set_v_3": {
					"base_score_v_3": "5.3",
					"vector_v_3": "CVSS:3.1/AV:N/AC:L/PR:N/UI:N/S:U/C:N/I:N/A:L"
				},
				"scoreset": {}
			},
			"remediations": [
				{
					"type": "Vendor Fix",
					"description": {
						"text": "To install this SUSE Security Update use the SUSE recommended installation methods like YaST online_update or \"zypper patch\".\n",
						"lang": "en"
					}
				}
			],
			"references": [
				{
					"url": "https://www.suse.com/security/cve/CVE-2019-20907.html",
					"description": "CVE-2019-20907"
				},
				{
					"url": "https://bugzilla.suse.com/1174091",
					"description": "SUSE Bug 1174091"
				}
			]
		},
		{
			"notes": [
				{
					"text": "An exploitable denial-of-service vulnerability exists in the X509 certificate parser of Python.org Python 2.7.11 / 3.6.6. A specially crafted X509 certificate can cause a NULL pointer dereference, resulting in a denial of service. An attacker can initiate or accept TLS connections using crafted certificates to trigger this vulnerability.",
					"title": "Vulnerability Description",
					"type": "General"
				}
			],
			"cve": "CVE-2019-5010",
			"product_statuses": [
				{
					"type": "Fixed",
					"product_id": [
						"openSUSE Tumbleweed:python313-3.13.0~b3-1.1",
						"openSUSE Tumbleweed:python313-curses-3.13.0~b3-1.1",
						"openSUSE Tumbleweed:python313-dbm-3.13.0~b3-1.1",
						"openSUSE Tumbleweed:python313-idle-3.13.0~b3-1.1",
						"openSUSE Tumbleweed:python313-tk-3.13.0~b3-1.1",
						"openSUSE Tumbleweed:python313-x86-64-v3-3.13.0~b3-1.1"
					]
				}
			],
			"threats": [
				{
					"type": "Impact",
					"description": "important"
				}
			],
			"cvss_score_sets": {
				"score_set_v_2": {
					"base_score_v_2": "5",
					"vector_v_2": "AV:N/AC:L/Au:N/C:N/I:N/A:P"
				},
				"score_set_v_3": {
					"base_score_v_3": "7.5",
					"vector_v_3": "CVSS:3.0/AV:N/AC:L/PR:N/UI:N/S:U/C:N/I:N/A:H"
				},
				"scoreset": {}
			},
			"remediations": [
				{
					"type": "Vendor Fix",
					"description": {
						"text": "To install this SUSE Security Update use the SUSE recommended installation methods like YaST online_update or \"zypper patch\".\n",
						"lang": "en"
					}
				}
			],
			"references": [
				{
					"url": "https://www.suse.com/security/cve/CVE-2019-5010.html",
					"description": "CVE-2019-5010"
				},
				{
					"url": "https://bugzilla.suse.com/1122191",
					"description": "SUSE Bug 1122191"
				},
				{
					"url": "https://bugzilla.suse.com/1126909",
					"description": "SUSE Bug 1126909"
				}
			]
		},
		{
			"notes": [
				{
					"text": "An issue was discovered in urllib2 in Python 2.x through 2.7.16 and urllib in Python 3.x through 3.7.3. CRLF injection is possible if the attacker controls a url parameter, as demonstrated by the first argument to urllib.request.urlopen with \\r\\n (specifically in the path component of a URL that lacks a ? character) followed by an HTTP header or a Redis command. This is similar to the CVE-2019-9740 query string issue. This is fixed in: v2.7.17, v2.7.17rc1, v2.7.18, v2.7.18rc1; v3.5.10, v3.5.10rc1, v3.5.8, v3.5.8rc1, v3.5.8rc2, v3.5.9; v3.6.10, v3.6.10rc1, v3.6.11, v3.6.11rc1, v3.6.12, v3.6.9, v3.6.9rc1; v3.7.4, v3.7.4rc1, v3.7.4rc2, v3.7.5, v3.7.5rc1, v3.7.6, v3.7.6rc1, v3.7.7, v3.7.7rc1, v3.7.8, v3.7.8rc1, v3.7.9.",
					"title": "Vulnerability Description",
					"type": "General"
				}
			],
			"cve": "CVE-2019-9947",
			"product_statuses": [
				{
					"type": "Fixed",
					"product_id": [
						"openSUSE Tumbleweed:python313-3.13.0~b3-1.1",
						"openSUSE Tumbleweed:python313-curses-3.13.0~b3-1.1",
						"openSUSE Tumbleweed:python313-dbm-3.13.0~b3-1.1",
						"openSUSE Tumbleweed:python313-idle-3.13.0~b3-1.1",
						"openSUSE Tumbleweed:python313-tk-3.13.0~b3-1.1",
						"openSUSE Tumbleweed:python313-x86-64-v3-3.13.0~b3-1.1"
					]
				}
			],
			"threats": [
				{
					"type": "Impact",
					"description": "moderate"
				}
			],
			"cvss_score_sets": {
				"score_set_v_2": {
					"base_score_v_2": "4.3",
					"vector_v_2": "AV:N/AC:M/Au:N/C:N/I:P/A:N"
				},
				"score_set_v_3": {
					"base_score_v_3": "5.4",
					"vector_v_3": "CVSS:3.0/AV:N/AC:H/PR:N/UI:N/S:C/C:L/I:L/A:N"
				},
				"scoreset": {}
			},
			"remediations": [
				{
					"type": "Vendor Fix",
					"description": {
						"text": "To install this SUSE Security Update use the SUSE recommended installation methods like YaST online_update or \"zypper patch\".\n",
						"lang": "en"
					}
				}
			],
			"references": [
				{
					"url": "https://www.suse.com/security/cve/CVE-2019-9947.html",
					"description": "CVE-2019-9947"
				},
				{
					"url": "https://bugzilla.suse.com/1130840",
					"description": "SUSE Bug 1130840"
				},
				{
					"url": "https://bugzilla.suse.com/1136184",
					"description": "SUSE Bug 1136184"
				},
				{
					"url": "https://bugzilla.suse.com/1155094",
					"description": "SUSE Bug 1155094"
				},
				{
					"url": "https://bugzilla.suse.com/1201559",
					"description": "SUSE Bug 1201559"
				}
			]
		},
		{
			"notes": [
				{
					"text": "A flaw was found in python. In algorithms with quadratic time complexity using non-binary bases, when using int(\"text\"), a system could take 50ms to parse an int string with 100,000 digits and 5s for 1,000,000 digits (float, decimal, int.from_bytes(), and int() for binary bases 2, 4, 8, 16, and 32 are not affected). The highest threat from this vulnerability is to system availability.",
					"title": "Vulnerability Description",
					"type": "General"
				}
			],
			"cve": "CVE-2020-10735",
			"product_statuses": [
				{
					"type": "Fixed",
					"product_id": [
						"openSUSE Tumbleweed:python313-3.13.0~b3-1.1",
						"openSUSE Tumbleweed:python313-curses-3.13.0~b3-1.1",
						"openSUSE Tumbleweed:python313-dbm-3.13.0~b3-1.1",
						"openSUSE Tumbleweed:python313-idle-3.13.0~b3-1.1",
						"openSUSE Tumbleweed:python313-tk-3.13.0~b3-1.1",
						"openSUSE Tumbleweed:python313-x86-64-v3-3.13.0~b3-1.1"
					]
				}
			],
			"threats": [
				{
					"type": "Impact",
					"description": "important"
				}
			],
			"cvss_score_sets": {
				"score_set_v_2": {},
				"score_set_v_3": {
					"base_score_v_3": "7.5",
					"vector_v_3": "CVSS:3.1/AV:N/AC:L/PR:N/UI:N/S:U/C:N/I:N/A:H"
				},
				"scoreset": {}
			},
			"remediations": [
				{
					"type": "Vendor Fix",
					"description": {
						"text": "To install this SUSE Security Update use the SUSE recommended installation methods like YaST online_update or \"zypper patch\".\n",
						"lang": "en"
					}
				}
			],
			"references": [
				{
					"url": "https://www.suse.com/security/cve/CVE-2020-10735.html",
					"description": "CVE-2020-10735"
				},
				{
					"url": "https://bugzilla.suse.com/1203125",
					"description": "SUSE Bug 1203125"
				},
				{
					"url": "https://bugzilla.suse.com/1204077",
					"description": "SUSE Bug 1204077"
				},
				{
					"url": "https://bugzilla.suse.com/1204096",
					"description": "SUSE Bug 1204096"
				},
				{
					"url": "https://bugzilla.suse.com/1204097",
					"description": "SUSE Bug 1204097"
				},
				{
					"url": "https://bugzilla.suse.com/1205075",
					"description": "SUSE Bug 1205075"
				},
				{
					"url": "https://bugzilla.suse.com/1208131",
					"description": "SUSE Bug 1208131"
				}
			]
		},
		{
			"notes": [
				{
					"text": "In Python 3.6 through 3.6.10, 3.7 through 3.7.8, 3.8 through 3.8.4rc1, and 3.9 through 3.9.0b4 on Windows, a Trojan horse python3.dll might be used in cases where CPython is embedded in a native application. This occurs because python3X.dll may use an invalid search path for python3.dll loading (after Py_SetPath has been used). NOTE: this issue CANNOT occur when using python.exe from a standard (non-embedded) Python installation on Windows.",
					"title": "Vulnerability Description",
					"type": "General"
				}
			],
			"cve": "CVE-2020-15523",
			"product_statuses": [
				{
					"type": "Fixed",
					"product_id": [
						"openSUSE Tumbleweed:python313-3.13.0~b3-1.1",
						"openSUSE Tumbleweed:python313-curses-3.13.0~b3-1.1",
						"openSUSE Tumbleweed:python313-dbm-3.13.0~b3-1.1",
						"openSUSE Tumbleweed:python313-idle-3.13.0~b3-1.1",
						"openSUSE Tumbleweed:python313-tk-3.13.0~b3-1.1",
						"openSUSE Tumbleweed:python313-x86-64-v3-3.13.0~b3-1.1"
					]
				}
			],
			"threats": [
				{
					"type": "Impact",
					"description": "important"
				}
			],
			"cvss_score_sets": {
				"score_set_v_2": {
					"base_score_v_2": "6.9",
					"vector_v_2": "AV:L/AC:M/Au:N/C:C/I:C/A:C"
				},
				"score_set_v_3": {
					"base_score_v_3": "7.8",
					"vector_v_3": "CVSS:3.1/AV:L/AC:L/PR:N/UI:R/S:U/C:H/I:H/A:H"
				},
				"scoreset": {}
			},
			"remediations": [
				{
					"type": "Vendor Fix",
					"description": {
						"text": "To install this SUSE Security Update use the SUSE recommended installation methods like YaST online_update or \"zypper patch\".\n",
						"lang": "en"
					}
				}
			],
			"references": [
				{
					"url": "https://www.suse.com/security/cve/CVE-2020-15523.html",
					"description": "CVE-2020-15523"
				},
				{
					"url": "https://bugzilla.suse.com/1173745",
					"description": "SUSE Bug 1173745"
				}
			]
		},
		{
			"notes": [
				{
					"text": "In Python 3.8.4, sys.path restrictions specified in a python38._pth file are ignored, allowing code to be loaded from arbitrary locations. The <executable-name>._pth file (e.g., the python._pth file) is not affected.",
					"title": "Vulnerability Description",
					"type": "General"
				}
			],
			"cve": "CVE-2020-15801",
			"product_statuses": [
				{
					"type": "Fixed",
					"product_id": [
						"openSUSE Tumbleweed:python313-3.13.0~b3-1.1",
						"openSUSE Tumbleweed:python313-curses-3.13.0~b3-1.1",
						"openSUSE Tumbleweed:python313-dbm-3.13.0~b3-1.1",
						"openSUSE Tumbleweed:python313-idle-3.13.0~b3-1.1",
						"openSUSE Tumbleweed:python313-tk-3.13.0~b3-1.1",
						"openSUSE Tumbleweed:python313-x86-64-v3-3.13.0~b3-1.1"
					]
				}
			],
			"threats": [
				{
					"type": "Impact",
					"description": "critical"
				}
			],
			"cvss_score_sets": {
				"score_set_v_2": {
					"base_score_v_2": "7.5",
					"vector_v_2": "AV:N/AC:L/Au:N/C:P/I:P/A:P"
				},
				"score_set_v_3": {
					"base_score_v_3": "9.8",
					"vector_v_3": "CVSS:3.1/AV:N/AC:L/PR:N/UI:N/S:U/C:H/I:H/A:H"
				},
				"scoreset": {}
			},
			"remediations": [
				{
					"type": "Vendor Fix",
					"description": {
						"text": "To install this SUSE Security Update use the SUSE recommended installation methods like YaST online_update or \"zypper patch\".\n",
						"lang": "en"
					}
				}
			],
			"references": [
				{
					"url": "https://www.suse.com/security/cve/CVE-2020-15801.html",
					"description": "CVE-2020-15801"
				},
				{
					"url": "https://bugzilla.suse.com/1174241",
					"description": "SUSE Bug 1174241"
				}
			]
		},
		{
			"notes": [
				{
					"text": "Python 2.7 through 2.7.17, 3.5 through 3.5.9, 3.6 through 3.6.10, 3.7 through 3.7.6, and 3.8 through 3.8.1 allows an HTTP server to conduct Regular Expression Denial of Service (ReDoS) attacks against a client because of urllib.request.AbstractBasicAuthHandler catastrophic backtracking.",
					"title": "Vulnerability Description",
					"type": "General"
				}
			],
			"cve": "CVE-2020-8492",
			"product_statuses": [
				{
					"type": "Fixed",
					"product_id": [
						"openSUSE Tumbleweed:python313-3.13.0~b3-1.1",
						"openSUSE Tumbleweed:python313-curses-3.13.0~b3-1.1",
						"openSUSE Tumbleweed:python313-dbm-3.13.0~b3-1.1",
						"openSUSE Tumbleweed:python313-idle-3.13.0~b3-1.1",
						"openSUSE Tumbleweed:python313-tk-3.13.0~b3-1.1",
						"openSUSE Tumbleweed:python313-x86-64-v3-3.13.0~b3-1.1"
					]
				}
			],
			"threats": [
				{
					"type": "Impact",
					"description": "moderate"
				}
			],
			"cvss_score_sets": {
				"score_set_v_2": {
					"base_score_v_2": "7.1",
					"vector_v_2": "AV:N/AC:M/Au:N/C:N/I:N/A:C"
				},
				"score_set_v_3": {
					"base_score_v_3": "6.5",
					"vector_v_3": "CVSS:3.1/AV:N/AC:L/PR:N/UI:R/S:U/C:N/I:N/A:H"
				},
				"scoreset": {}
			},
			"remediations": [
				{
					"type": "Vendor Fix",
					"description": {
						"text": "To install this SUSE Security Update use the SUSE recommended installation methods like YaST online_update or \"zypper patch\".\n",
						"lang": "en"
					}
				}
			],
			"references": [
				{
					"url": "https://www.suse.com/security/cve/CVE-2020-8492.html",
					"description": "CVE-2020-8492"
				},
				{
					"url": "https://bugzilla.suse.com/1162367",
					"description": "SUSE Bug 1162367"
				}
			]
		},
		{
			"notes": [
				{
					"text": "The package python/cpython from 0 and before 3.6.13, from 3.7.0 and before 3.7.10, from 3.8.0 and before 3.8.8, from 3.9.0 and before 3.9.2 are vulnerable to Web Cache Poisoning via urllib.parse.parse_qsl and urllib.parse.parse_qs by using a vector called parameter cloaking. When the attacker can separate query parameters using a semicolon (;), they can cause a difference in the interpretation of the request between the proxy (running with default configuration) and the server. This can result in malicious requests being cached as completely safe ones, as the proxy would usually not see the semicolon as a separator, and therefore would not include it in a cache key of an unkeyed parameter.",
					"title": "Vulnerability Description",
					"type": "General"
				}
			],
			"cve": "CVE-2021-23336",
			"product_statuses": [
				{
					"type": "Fixed",
					"product_id": [
						"openSUSE Tumbleweed:python313-3.13.0~b3-1.1",
						"openSUSE Tumbleweed:python313-curses-3.13.0~b3-1.1",
						"openSUSE Tumbleweed:python313-dbm-3.13.0~b3-1.1",
						"openSUSE Tumbleweed:python313-idle-3.13.0~b3-1.1",
						"openSUSE Tumbleweed:python313-tk-3.13.0~b3-1.1",
						"openSUSE Tumbleweed:python313-x86-64-v3-3.13.0~b3-1.1"
					]
				}
			],
			"threats": [
				{
					"type": "Impact",
					"description": "moderate"
				}
			],
			"cvss_score_sets": {
				"score_set_v_2": {
					"base_score_v_2": "4",
					"vector_v_2": "AV:N/AC:H/Au:N/C:N/I:P/A:P"
				},
				"score_set_v_3": {
					"base_score_v_3": "5.9",
					"vector_v_3": "CVSS:3.1/AV:N/AC:H/PR:N/UI:R/S:U/C:N/I:L/A:H"
				},
				"scoreset": {}
			},
			"remediations": [
				{
					"type": "Vendor Fix",
					"description": {
						"text": "To install this SUSE Security Update use the SUSE recommended installation methods like YaST online_update or \"zypper patch\".\n",
						"lang": "en"
					}
				}
			],
			"references": [
				{
					"url": "https://www.suse.com/security/cve/CVE-2021-23336.html",
					"description": "CVE-2021-23336"
				},
				{
					"url": "https://bugzilla.suse.com/1182179",
					"description": "SUSE Bug 1182179"
				},
				{
					"url": "https://bugzilla.suse.com/1182379",
					"description": "SUSE Bug 1182379"
				},
				{
					"url": "https://bugzilla.suse.com/1182433",
					"description": "SUSE Bug 1182433"
				}
			]
		},
		{
			"notes": [
				{
					"text": "Python 3.x through 3.9.1 has a buffer overflow in PyCArg_repr in _ctypes/callproc.c, which may lead to remote code execution in certain Python applications that accept floating-point numbers as untrusted input, as demonstrated by a 1e300 argument to c_double.from_param. This occurs because sprintf is used unsafely.",
					"title": "Vulnerability Description",
					"type": "General"
				}
			],
			"cve": "CVE-2021-3177",
			"product_statuses": [
				{
					"type": "Fixed",
					"product_id": [
						"openSUSE Tumbleweed:python313-3.13.0~b3-1.1",
						"openSUSE Tumbleweed:python313-curses-3.13.0~b3-1.1",
						"openSUSE Tumbleweed:python313-dbm-3.13.0~b3-1.1",
						"openSUSE Tumbleweed:python313-idle-3.13.0~b3-1.1",
						"openSUSE Tumbleweed:python313-tk-3.13.0~b3-1.1",
						"openSUSE Tumbleweed:python313-x86-64-v3-3.13.0~b3-1.1"
					]
				}
			],
			"threats": [
				{
					"type": "Impact",
					"description": "moderate"
				}
			],
			"cvss_score_sets": {
				"score_set_v_2": {
					"base_score_v_2": "7.5",
					"vector_v_2": "AV:N/AC:L/Au:N/C:P/I:P/A:P"
				},
				"score_set_v_3": {
					"base_score_v_3": "5.9",
					"vector_v_3": "CVSS:3.1/AV:N/AC:H/PR:N/UI:N/S:U/C:N/I:N/A:H"
				},
				"scoreset": {}
			},
			"remediations": [
				{
					"type": "Vendor Fix",
					"description": {
						"text": "To install this SUSE Security Update use the SUSE recommended installation methods like YaST online_update or \"zypper patch\".\n",
						"lang": "en"
					}
				}
			],
			"references": [
				{
					"url": "https://www.suse.com/security/cve/CVE-2021-3177.html",
					"description": "CVE-2021-3177"
				},
				{
					"url": "https://bugzilla.suse.com/1181126",
					"description": "SUSE Bug 1181126"
				}
			]
		},
		{
			"notes": [
				{
					"text": "There's a flaw in Python 3's pydoc. A local or adjacent attacker who discovers or is able to convince another local or adjacent user to start a pydoc server could access the server and use it to disclose sensitive information belonging to the other user that they would not normally be able to access. The highest risk of this flaw is to data confidentiality. This flaw affects Python versions before 3.8.9, Python versions before 3.9.3 and Python versions before 3.10.0a7.",
					"title": "Vulnerability Description",
					"type": "General"
				}
			],
			"cve": "CVE-2021-3426",
			"product_statuses": [
				{
					"type": "Fixed",
					"product_id": [
						"openSUSE Tumbleweed:python313-3.13.0~b3-1.1",
						"openSUSE Tumbleweed:python313-curses-3.13.0~b3-1.1",
						"openSUSE Tumbleweed:python313-dbm-3.13.0~b3-1.1",
						"openSUSE Tumbleweed:python313-idle-3.13.0~b3-1.1",
						"openSUSE Tumbleweed:python313-tk-3.13.0~b3-1.1",
						"openSUSE Tumbleweed:python313-x86-64-v3-3.13.0~b3-1.1"
					]
				}
			],
			"threats": [
				{
					"type": "Impact",
					"description": "moderate"
				}
			],
			"cvss_score_sets": {
				"score_set_v_2": {
					"base_score_v_2": "2.7",
					"vector_v_2": "AV:A/AC:L/Au:S/C:P/I:N/A:N"
				},
				"score_set_v_3": {
					"base_score_v_3": "5.5",
					"vector_v_3": "CVSS:3.1/AV:L/AC:L/PR:L/UI:N/S:U/C:H/I:N/A:N"
				},
				"scoreset": {}
			},
			"remediations": [
				{
					"type": "Vendor Fix",
					"description": {
						"text": "To install this SUSE Security Update use the SUSE recommended installation methods like YaST online_update or \"zypper patch\".\n",
						"lang": "en"
					}
				}
			],
			"references": [
				{
					"url": "https://www.suse.com/security/cve/CVE-2021-3426.html",
					"description": "CVE-2021-3426"
				},
				{
					"url": "https://bugzilla.suse.com/1183374",
					"description": "SUSE Bug 1183374"
				}
			]
		},
		{
			"notes": [
				{
					"text": "xmlparse.c in Expat (aka libexpat) before 2.4.5 allows attackers to insert namespace-separator characters into namespace URIs.",
					"title": "Vulnerability Description",
					"type": "General"
				}
			],
			"cve": "CVE-2022-25236",
			"product_statuses": [
				{
					"type": "Fixed",
					"product_id": [
						"openSUSE Tumbleweed:python313-3.13.0~b3-1.1",
						"openSUSE Tumbleweed:python313-curses-3.13.0~b3-1.1",
						"openSUSE Tumbleweed:python313-dbm-3.13.0~b3-1.1",
						"openSUSE Tumbleweed:python313-idle-3.13.0~b3-1.1",
						"openSUSE Tumbleweed:python313-tk-3.13.0~b3-1.1",
						"openSUSE Tumbleweed:python313-x86-64-v3-3.13.0~b3-1.1"
					]
				}
			],
			"threats": [
				{
					"type": "Impact",
					"description": "important"
				}
			],
			"cvss_score_sets": {
				"score_set_v_2": {
					"base_score_v_2": "7.5",
					"vector_v_2": "AV:N/AC:L/Au:N/C:P/I:P/A:P"
				},
				"score_set_v_3": {
					"base_score_v_3": "7.5",
					"vector_v_3": "CVSS:3.1/AV:N/AC:H/PR:N/UI:R/S:U/C:H/I:H/A:H"
				},
				"scoreset": {}
			},
			"remediations": [
				{
					"type": "Vendor Fix",
					"description": {
						"text": "To install this SUSE Security Update use the SUSE recommended installation methods like YaST online_update or \"zypper patch\".\n",
						"lang": "en"
					}
				}
			],
			"references": [
				{
					"url": "https://www.suse.com/security/cve/CVE-2022-25236.html",
					"description": "CVE-2022-25236"
				},
				{
					"url": "https://bugzilla.suse.com/1196025",
					"description": "SUSE Bug 1196025"
				},
				{
					"url": "https://bugzilla.suse.com/1196784",
					"description": "SUSE Bug 1196784"
				},
				{
					"url": "https://bugzilla.suse.com/1197217",
					"description": "SUSE Bug 1197217"
				},
				{
					"url": "https://bugzilla.suse.com/1200038",
					"description": "SUSE Bug 1200038"
				},
				{
					"url": "https://bugzilla.suse.com/1201735",
					"description": "SUSE Bug 1201735"
				}
			]
		},
		{
			"notes": [
				{
					"text": "Python 3.9.x before 3.9.16 and 3.10.x before 3.10.9 on Linux allows local privilege escalation in a non-default configuration. The Python multiprocessing library, when used with the forkserver start method on Linux, allows pickles to be deserialized from any user in the same machine local network namespace, which in many system configurations means any user on the same machine. Pickles can execute arbitrary code. Thus, this allows for local user privilege escalation to the user that any forkserver process is running as. Setting multiprocessing.util.abstract_sockets_supported to False is a workaround. The forkserver start method for multiprocessing is not the default start method. This issue is Linux specific because only Linux supports abstract namespace sockets. CPython before 3.9 does not make use of Linux abstract namespace sockets by default. Support for users manually specifying an abstract namespace socket was added as a bugfix in 3.7.8 and 3.8.3, but users would need to make specific uncommon API calls in order to do that in CPython before 3.9.",
					"title": "Vulnerability Description",
					"type": "General"
				}
			],
			"cve": "CVE-2022-42919",
			"product_statuses": [
				{
					"type": "Fixed",
					"product_id": [
						"openSUSE Tumbleweed:python313-3.13.0~b3-1.1",
						"openSUSE Tumbleweed:python313-curses-3.13.0~b3-1.1",
						"openSUSE Tumbleweed:python313-dbm-3.13.0~b3-1.1",
						"openSUSE Tumbleweed:python313-idle-3.13.0~b3-1.1",
						"openSUSE Tumbleweed:python313-tk-3.13.0~b3-1.1",
						"openSUSE Tumbleweed:python313-x86-64-v3-3.13.0~b3-1.1"
					]
				}
			],
			"threats": [
				{
					"type": "Impact",
					"description": "important"
				}
			],
			"cvss_score_sets": {
				"score_set_v_2": {},
				"score_set_v_3": {
					"base_score_v_3": "7.8",
					"vector_v_3": "CVSS:3.1/AV:L/AC:L/PR:L/UI:N/S:U/C:H/I:H/A:H"
				},
				"scoreset": {}
			},
			"remediations": [
				{
					"type": "Vendor Fix",
					"description": {
						"text": "To install this SUSE Security Update use the SUSE recommended installation methods like YaST online_update or \"zypper patch\".\n",
						"lang": "en"
					}
				}
			],
			"references": [
				{
					"url": "https://www.suse.com/security/cve/CVE-2022-42919.html",
					"description": "CVE-2022-42919"
				},
				{
					"url": "https://bugzilla.suse.com/1204886",
					"description": "SUSE Bug 1204886"
				}
			]
		},
		{
			"notes": [
				{
					"text": "An issue was discovered in Python before 3.11.1. An unnecessary quadratic algorithm exists in one path when processing some inputs to the IDNA (RFC 3490) decoder, such that a crafted, unreasonably long name being presented to the decoder could lead to a CPU denial of service. Hostnames are often supplied by remote servers that could be controlled by a malicious actor; in such a scenario, they could trigger excessive CPU consumption on the client attempting to make use of an attacker-supplied supposed hostname. For example, the attack payload could be placed in the Location header of an HTTP response with status code 302. A fix is planned in 3.11.1, 3.10.9, 3.9.16, 3.8.16, and 3.7.16.",
					"title": "Vulnerability Description",
					"type": "General"
				}
			],
			"cve": "CVE-2022-45061",
			"product_statuses": [
				{
					"type": "Fixed",
					"product_id": [
						"openSUSE Tumbleweed:python313-3.13.0~b3-1.1",
						"openSUSE Tumbleweed:python313-curses-3.13.0~b3-1.1",
						"openSUSE Tumbleweed:python313-dbm-3.13.0~b3-1.1",
						"openSUSE Tumbleweed:python313-idle-3.13.0~b3-1.1",
						"openSUSE Tumbleweed:python313-tk-3.13.0~b3-1.1",
						"openSUSE Tumbleweed:python313-x86-64-v3-3.13.0~b3-1.1"
					]
				}
			],
			"threats": [
				{
					"type": "Impact",
					"description": "moderate"
				}
			],
			"cvss_score_sets": {
				"score_set_v_2": {},
				"score_set_v_3": {
					"base_score_v_3": "6.5",
					"vector_v_3": "CVSS:3.1/AV:N/AC:L/PR:N/UI:R/S:U/C:N/I:N/A:H"
				},
				"scoreset": {}
			},
			"remediations": [
				{
					"type": "Vendor Fix",
					"description": {
						"text": "To install this SUSE Security Update use the SUSE recommended installation methods like YaST online_update or \"zypper patch\".\n",
						"lang": "en"
					}
				}
			],
			"references": [
				{
					"url": "https://www.suse.com/security/cve/CVE-2022-45061.html",
					"description": "CVE-2022-45061"
				},
				{
					"url": "https://bugzilla.suse.com/1205244",
					"description": "SUSE Bug 1205244"
				},
				{
					"url": "https://bugzilla.suse.com/1211488",
					"description": "SUSE Bug 1211488"
				}
			]
		},
		{
			"notes": [
				{
					"text": "There is a type confusion vulnerability relating to X.400 address processing\ninside an X.509 GeneralName. X.400 addresses were parsed as an ASN1_STRING but\nthe public structure definition for GENERAL_NAME incorrectly specified the type\nof the x400Address field as ASN1_TYPE. This field is subsequently interpreted by\nthe OpenSSL function GENERAL_NAME_cmp as an ASN1_TYPE rather than an\nASN1_STRING.\n\nWhen CRL checking is enabled (i.e. the application sets the\nX509_V_FLAG_CRL_CHECK flag), this vulnerability may allow an attacker to pass\narbitrary pointers to a memcmp call, enabling them to read memory contents or\nenact a denial of service. In most cases, the attack requires the attacker to\nprovide both the certificate chain and CRL, neither of which need to have a\nvalid signature. If the attacker only controls one of these inputs, the other\ninput must already contain an X.400 address as a CRL distribution point, which\nis uncommon. As such, this vulnerability is most likely to only affect\napplications which have implemented their own functionality for retrieving CRLs\nover a network.\n\n",
					"title": "Vulnerability Description",
					"type": "General"
				}
			],
			"cve": "CVE-2023-0286",
			"product_statuses": [
				{
					"type": "Fixed",
					"product_id": [
						"openSUSE Tumbleweed:python313-3.13.0~b3-1.1",
						"openSUSE Tumbleweed:python313-curses-3.13.0~b3-1.1",
						"openSUSE Tumbleweed:python313-dbm-3.13.0~b3-1.1",
						"openSUSE Tumbleweed:python313-idle-3.13.0~b3-1.1",
						"openSUSE Tumbleweed:python313-tk-3.13.0~b3-1.1",
						"openSUSE Tumbleweed:python313-x86-64-v3-3.13.0~b3-1.1"
					]
				}
			],
			"threats": [
				{
					"type": "Impact",
					"description": "important"
				}
			],
			"cvss_score_sets": {
				"score_set_v_2": {},
				"score_set_v_3": {
					"base_score_v_3": "7.4",
					"vector_v_3": "CVSS:3.1/AV:N/AC:H/PR:N/UI:N/S:U/C:H/I:N/A:H"
				},
				"scoreset": {}
			},
			"remediations": [
				{
					"type": "Vendor Fix",
					"description": {
						"text": "To install this SUSE Security Update use the SUSE recommended installation methods like YaST online_update or \"zypper patch\".\n",
						"lang": "en"
					}
				}
			],
			"references": [
				{
					"url": "https://www.suse.com/security/cve/CVE-2023-0286.html",
					"description": "CVE-2023-0286"
				},
				{
					"url": "https://bugzilla.suse.com/1207533",
					"description": "SUSE Bug 1207533"
				},
				{
					"url": "https://bugzilla.suse.com/1207569",
					"description": "SUSE Bug 1207569"
				},
				{
					"url": "https://bugzilla.suse.com/1211136",
					"description": "SUSE Bug 1211136"
				},
				{
					"url": "https://bugzilla.suse.com/1211503",
					"description": "SUSE Bug 1211503"
				},
				{
					"url": "https://bugzilla.suse.com/1213146",
					"description": "SUSE Bug 1213146"
				},
				{
					"url": "https://bugzilla.suse.com/1214269",
					"description": "SUSE Bug 1214269"
				},
				{
					"url": "https://bugzilla.suse.com/1218477",
					"description": "SUSE Bug 1218477"
				},
				{
					"url": "https://bugzilla.suse.com/1218967",
					"description": "SUSE Bug 1218967"
				},
				{
					"url": "https://bugzilla.suse.com/1225677",
					"description": "SUSE Bug 1225677"
				}
			]
		},
		{
			"notes": [
				{
					"text": "An issue in the urllib.parse component of Python before 3.11.4 allows attackers to bypass blocklisting methods by supplying a URL that starts with blank characters.",
					"title": "Vulnerability Description",
					"type": "General"
				}
			],
			"cve": "CVE-2023-24329",
			"product_statuses": [
				{
					"type": "Fixed",
					"product_id": [
						"openSUSE Tumbleweed:python313-3.13.0~b3-1.1",
						"openSUSE Tumbleweed:python313-curses-3.13.0~b3-1.1",
						"openSUSE Tumbleweed:python313-dbm-3.13.0~b3-1.1",
						"openSUSE Tumbleweed:python313-idle-3.13.0~b3-1.1",
						"openSUSE Tumbleweed:python313-tk-3.13.0~b3-1.1",
						"openSUSE Tumbleweed:python313-x86-64-v3-3.13.0~b3-1.1"
					]
				}
			],
			"threats": [
				{
					"type": "Impact",
					"description": "important"
				}
			],
			"cvss_score_sets": {
				"score_set_v_2": {},
				"score_set_v_3": {
					"base_score_v_3": "7.3",
					"vector_v_3": "CVSS:3.1/AV:L/AC:L/PR:N/UI:N/S:U/C:H/I:L/A:L"
				},
				"scoreset": {}
			},
			"remediations": [
				{
					"type": "Vendor Fix",
					"description": {
						"text": "To install this SUSE Security Update use the SUSE recommended installation methods like YaST online_update or \"zypper patch\".\n",
						"lang": "en"
					}
				}
			],
			"references": [
				{
					"url": "https://www.suse.com/security/cve/CVE-2023-24329.html",
					"description": "CVE-2023-24329"
				},
				{
					"url": "https://bugzilla.suse.com/1208471",
					"description": "SUSE Bug 1208471"
				},
				{
					"url": "https://bugzilla.suse.com/1213553",
					"description": "SUSE Bug 1213553"
				},
				{
					"url": "https://bugzilla.suse.com/1213554",
					"description": "SUSE Bug 1213554"
				},
				{
					"url": "https://bugzilla.suse.com/1213839",
					"description": "SUSE Bug 1213839"
				},
				{
					"url": "https://bugzilla.suse.com/1225672",
					"description": "SUSE Bug 1225672"
				}
			]
		},
		{
			"notes": [
				{
					"text": "Issue summary: Processing some specially crafted ASN.1 object identifiers or\ndata containing them may be very slow.\n\nImpact summary: Applications that use OBJ_obj2txt() directly, or use any of\nthe OpenSSL subsystems OCSP, PKCS7/SMIME, CMS, CMP/CRMF or TS with no message\nsize limit may experience notable to very long delays when processing those\nmessages, which may lead to a Denial of Service.\n\nAn OBJECT IDENTIFIER is composed of a series of numbers - sub-identifiers -\nmost of which have no size limit.  OBJ_obj2txt() may be used to translate\nan ASN.1 OBJECT IDENTIFIER given in DER encoding form (using the OpenSSL\ntype ASN1_OBJECT) to its canonical numeric text form, which are the\nsub-identifiers of the OBJECT IDENTIFIER in decimal form, separated by\nperiods.\n\nWhen one of the sub-identifiers in the OBJECT IDENTIFIER is very large\n(these are sizes that are seen as absurdly large, taking up tens or hundreds\nof KiBs), the translation to a decimal number in text may take a very long\ntime.  The time complexity is O(n^2) with 'n' being the size of the\nsub-identifiers in bytes (*).\n\nWith OpenSSL 3.0, support to fetch cryptographic algorithms using names /\nidentifiers in string form was introduced.  This includes using OBJECT\nIDENTIFIERs in canonical numeric text form as identifiers for fetching\nalgorithms.\n\nSuch OBJECT IDENTIFIERs may be received through the ASN.1 structure\nAlgorithmIdentifier, which is commonly used in multiple protocols to specify\nwhat cryptographic algorithm should be used to sign or verify, encrypt or\ndecrypt, or digest passed data.\n\nApplications that call OBJ_obj2txt() directly with untrusted data are\naffected, with any version of OpenSSL.  If the use is for the mere purpose\nof display, the severity is considered low.\n\nIn OpenSSL 3.0 and newer, this affects the subsystems OCSP, PKCS7/SMIME,\nCMS, CMP/CRMF or TS.  It also impacts anything that processes X.509\ncertificates, including simple things like verifying its signature.\n\nThe impact on TLS is relatively low, because all versions of OpenSSL have a\n100KiB limit on the peer's certificate chain.  Additionally, this only\nimpacts clients, or servers that have explicitly enabled client\nauthentication.\n\nIn OpenSSL 1.1.1 and 1.0.2, this only affects displaying diverse objects,\nsuch as X.509 certificates.  This is assumed to not happen in such a way\nthat it would cause a Denial of Service, so these versions are considered\nnot affected by this issue in such a way that it would be cause for concern,\nand the severity is therefore considered low.",
					"title": "Vulnerability Description",
					"type": "General"
				}
			],
			"cve": "CVE-2023-2650",
			"product_statuses": [
				{
					"type": "Fixed",
					"product_id": [
						"openSUSE Tumbleweed:python313-3.13.0~b3-1.1",
						"openSUSE Tumbleweed:python313-curses-3.13.0~b3-1.1",
						"openSUSE Tumbleweed:python313-dbm-3.13.0~b3-1.1",
						"openSUSE Tumbleweed:python313-idle-3.13.0~b3-1.1",
						"openSUSE Tumbleweed:python313-tk-3.13.0~b3-1.1",
						"openSUSE Tumbleweed:python313-x86-64-v3-3.13.0~b3-1.1"
					]
				}
			],
			"threats": [
				{
					"type": "Impact",
					"description": "moderate"
				}
			],
			"cvss_score_sets": {
				"score_set_v_2": {},
				"score_set_v_3": {
					"base_score_v_3": "6.5",
					"vector_v_3": "CVSS:3.1/AV:N/AC:L/PR:N/UI:R/S:U/C:N/I:N/A:H"
				},
				"scoreset": {}
			},
			"remediations": [
				{
					"type": "Vendor Fix",
					"description": {
						"text": "To install this SUSE Security Update use the SUSE recommended installation methods like YaST online_update or \"zypper patch\".\n",
						"lang": "en"
					}
				}
			],
			"references": [
				{
					"url": "https://www.suse.com/security/cve/CVE-2023-2650.html",
					"description": "CVE-2023-2650"
				},
				{
					"url": "https://bugzilla.suse.com/1211430",
					"description": "SUSE Bug 1211430"
				}
			]
		},
		{
			"notes": [
				{
					"text": "The email module of Python through 3.11.3 incorrectly parses e-mail addresses that contain a special character. The wrong portion of an RFC2822 header is identified as the value of the addr-spec. In some applications, an attacker can bypass a protection mechanism in which application access is granted only after verifying receipt of e-mail to a specific domain (e.g., only @company.example.com addresses may be used for signup). This occurs in email/_parseaddr.py in recent versions of Python.",
					"title": "Vulnerability Description",
					"type": "General"
				}
			],
			"cve": "CVE-2023-27043",
			"product_statuses": [
				{
					"type": "Fixed",
					"product_id": [
						"openSUSE Tumbleweed:python313-3.13.0~b3-1.1",
						"openSUSE Tumbleweed:python313-curses-3.13.0~b3-1.1",
						"openSUSE Tumbleweed:python313-dbm-3.13.0~b3-1.1",
						"openSUSE Tumbleweed:python313-idle-3.13.0~b3-1.1",
						"openSUSE Tumbleweed:python313-tk-3.13.0~b3-1.1",
						"openSUSE Tumbleweed:python313-x86-64-v3-3.13.0~b3-1.1"
					]
				}
			],
			"threats": [
				{
					"type": "Impact",
					"description": "moderate"
				}
			],
			"cvss_score_sets": {
				"score_set_v_2": {},
				"score_set_v_3": {
					"base_score_v_3": "5.3",
					"vector_v_3": "CVSS:3.1/AV:N/AC:L/PR:N/UI:N/S:U/C:N/I:L/A:N"
				},
				"scoreset": {}
			},
			"remediations": [
				{
					"type": "Vendor Fix",
					"description": {
						"text": "To install this SUSE Security Update use the SUSE recommended installation methods like YaST online_update or \"zypper patch\".\n",
						"lang": "en"
					}
				}
			],
			"references": [
				{
					"url": "https://www.suse.com/security/cve/CVE-2023-27043.html",
					"description": "CVE-2023-27043"
				},
				{
					"url": "https://bugzilla.suse.com/1210638",
					"description": "SUSE Bug 1210638"
				},
				{
					"url": "https://bugzilla.suse.com/1222537",
					"description": "SUSE Bug 1222537"
				}
			]
		},
		{
			"notes": [
				{
					"text": "An issue was discovered in Python before 3.8.18, 3.9.x before 3.9.18, 3.10.x before 3.10.13, and 3.11.x before 3.11.5. It primarily affects servers (such as HTTP servers) that use TLS client authentication. If a TLS server-side socket is created, receives data into the socket buffer, and then is closed quickly, there is a brief window where the SSLSocket instance will detect the socket as \"not connected\" and won't initiate a handshake, but buffered data will still be readable from the socket buffer. This data will not be authenticated if the server-side TLS peer is expecting client certificate authentication, and is indistinguishable from valid TLS stream data. Data is limited in size to the amount that will fit in the buffer. (The TLS connection cannot directly be used for data exfiltration because the vulnerable code path requires that the connection be closed on initialization of the SSLSocket.)",
					"title": "Vulnerability Description",
					"type": "General"
				}
			],
			"cve": "CVE-2023-40217",
			"product_statuses": [
				{
					"type": "Fixed",
					"product_id": [
						"openSUSE Tumbleweed:python313-3.13.0~b3-1.1",
						"openSUSE Tumbleweed:python313-curses-3.13.0~b3-1.1",
						"openSUSE Tumbleweed:python313-dbm-3.13.0~b3-1.1",
						"openSUSE Tumbleweed:python313-idle-3.13.0~b3-1.1",
						"openSUSE Tumbleweed:python313-tk-3.13.0~b3-1.1",
						"openSUSE Tumbleweed:python313-x86-64-v3-3.13.0~b3-1.1"
					]
				}
			],
			"threats": [
				{
					"type": "Impact",
					"description": "important"
				}
			],
			"cvss_score_sets": {
				"score_set_v_2": {},
				"score_set_v_3": {
					"base_score_v_3": "7.4",
					"vector_v_3": "CVSS:3.1/AV:N/AC:H/PR:N/UI:N/S:U/C:H/I:H/A:N"
				},
				"scoreset": {}
			},
			"remediations": [
				{
					"type": "Vendor Fix",
					"description": {
						"text": "To install this SUSE Security Update use the SUSE recommended installation methods like YaST online_update or \"zypper patch\".\n",
						"lang": "en"
					}
				}
			],
			"references": [
				{
					"url": "https://www.suse.com/security/cve/CVE-2023-40217.html",
					"description": "CVE-2023-40217"
				},
				{
					"url": "https://bugzilla.suse.com/1214692",
					"description": "SUSE Bug 1214692"
				},
				{
					"url": "https://bugzilla.suse.com/1217524",
					"description": "SUSE Bug 1217524"
				},
				{
					"url": "https://bugzilla.suse.com/1218319",
					"description": "SUSE Bug 1218319"
				},
				{
					"url": "https://bugzilla.suse.com/1218476",
					"description": "SUSE Bug 1218476"
				},
				{
					"url": "https://bugzilla.suse.com/1218965",
					"description": "SUSE Bug 1218965"
				},
				{
					"url": "https://bugzilla.suse.com/1219472",
					"description": "SUSE Bug 1219472"
				},
				{
					"url": "https://bugzilla.suse.com/1219713",
					"description": "SUSE Bug 1219713"
				},
				{
					"url": "https://bugzilla.suse.com/1221582",
					"description": "SUSE Bug 1221582"
				},
				{
					"url": "https://bugzilla.suse.com/1224883",
					"description": "SUSE Bug 1224883"
				}
			]
		},
		{
			"notes": [
				{
					"text": "libexpat through 2.5.0 allows a denial of service (resource consumption) because many full reparsings are required in the case of a large token for which multiple buffer fills are needed.",
					"title": "Vulnerability Description",
					"type": "General"
				}
			],
			"cve": "CVE-2023-52425",
			"product_statuses": [
				{
					"type": "Fixed",
					"product_id": [
						"openSUSE Tumbleweed:python313-3.13.0~b3-1.1",
						"openSUSE Tumbleweed:python313-curses-3.13.0~b3-1.1",
						"openSUSE Tumbleweed:python313-dbm-3.13.0~b3-1.1",
						"openSUSE Tumbleweed:python313-idle-3.13.0~b3-1.1",
						"openSUSE Tumbleweed:python313-tk-3.13.0~b3-1.1",
						"openSUSE Tumbleweed:python313-x86-64-v3-3.13.0~b3-1.1"
					]
				}
			],
			"threats": [
				{
					"type": "Impact",
					"description": "moderate"
				}
			],
			"cvss_score_sets": {
				"score_set_v_2": {},
				"score_set_v_3": {
					"base_score_v_3": "5.5",
					"vector_v_3": "CVSS:3.1/AV:L/AC:L/PR:L/UI:N/S:U/C:N/I:N/A:H"
				},
				"scoreset": {}
			},
			"remediations": [
				{
					"type": "Vendor Fix",
					"description": {
						"text": "To install this SUSE Security Update use the SUSE recommended installation methods like YaST online_update or \"zypper patch\".\n",
						"lang": "en"
					}
				}
			],
			"references": [
				{
					"url": "https://www.suse.com/security/cve/CVE-2023-52425.html",
					"description": "CVE-2023-52425"
				},
				{
					"url": "https://bugzilla.suse.com/1219559",
					"description": "SUSE Bug 1219559"
				}
			]
		},
		{
			"notes": [
				{
					"text": "On Windows a directory returned by tempfile.mkdtemp() would not always have permissions set to restrict reading and writing to the temporary directory by other users, instead usually inheriting the correct permissions from the default location. Alternate configurations or users without a profile directory may not have the intended permissions.\n\nIf you're not using Windows or haven't changed the temporary directory location then you aren't affected by this vulnerability. On other platforms the returned directory is consistently readable and writable only by the current user.\n\nThis issue was caused by Python not supporting Unix permissions on Windows. The fix adds support for Unix \"700\" for the mkdir function on Windows which is used by mkdtemp() to ensure the newly created directory has the proper permissions.\n",
					"title": "Vulnerability Description",
					"type": "General"
				}
			],
			"cve": "CVE-2024-4030",
			"product_statuses": [
				{
					"type": "Fixed",
					"product_id": [
						"openSUSE Tumbleweed:python313-3.13.0~b3-1.1",
						"openSUSE Tumbleweed:python313-curses-3.13.0~b3-1.1",
						"openSUSE Tumbleweed:python313-dbm-3.13.0~b3-1.1",
						"openSUSE Tumbleweed:python313-idle-3.13.0~b3-1.1",
						"openSUSE Tumbleweed:python313-tk-3.13.0~b3-1.1",
						"openSUSE Tumbleweed:python313-x86-64-v3-3.13.0~b3-1.1"
					]
				}
			],
			"threats": [
				{
					"type": "Impact",
					"description": "moderate"
				}
			],
			"cvss_score_sets": {
				"score_set_v_2": {},
				"score_set_v_3": {
					"base_score_v_3": "4.4",
					"vector_v_3": "CVSS:3.1/AV:L/AC:L/PR:L/UI:N/S:U/C:L/I:L/A:N"
				},
				"scoreset": {}
			},
			"remediations": [
				{
					"type": "Vendor Fix",
					"description": {
						"text": "To install this SUSE Security Update use the SUSE recommended installation methods like YaST online_update or \"zypper patch\".\n",
						"lang": "en"
					}
				}
			],
			"references": [
				{
					"url": "https://www.suse.com/security/cve/CVE-2024-4030.html",
					"description": "CVE-2024-4030"
				},
				{
					"url": "https://bugzilla.suse.com/1227152",
					"description": "SUSE Bug 1227152"
				}
			]
		}
	]
}
